Workbook

Sheet Auswertung Gesamt
A1: Name | B1: Summe
A2: Conni K | B2: =SUM('Auswertung Stage'!B4:V4) -> 428
A3: Cindy | B3: =SUM('Auswertung Stage'!B3:V3) -> 367
A4: Sebbo | B4: =SUM('Auswertung Stage'!B9:V9) -> 394
A5: Lanci | B5: =SUM('Auswertung Stage'!B8:V8) -> 370
A6: Till | B6: =SUM('Auswertung Stage'!B11:V11) -> 388
A7: Richard NB | B7: =SUM('Auswertung Stage'!B15:V15) -> 471
A8: Jakob | B8: =SUM('Auswertung Stage'!B2:V2) -> 373
A9: Lea | B9: =SUM('Auswertung Stage'!B7:V7) -> 345
A10: Chris | B10: =SUM('Auswertung Stage'!B5:V5) -> 367
A11: Jule | B11: =SUM('Auswertung Stage'!B14:V14) -> 327
A12: Konsti | B12: =SUM('Auswertung Stage'!B13:V13) -> 296
A13: Nora | B13: =SUM('Auswertung Stage'!B6:V6) -> 309
A14: Reto | B14: =SUM('Auswertung Stage'!B12:V12) -> 420
A15: Simi | B15: =SUM('Auswertung Stage'!B18:V18) -> 370
A16: Rikki | B16: =SUM('Auswertung Stage'!B16:V16) -> 380
A17: Bendix | B17: =SUM('Auswertung Stage'!B10:V10) -> 339
A18: Chrysli | B18: =SUM('Auswertung Stage'!B17:V17) -> 204

Sheet Auswertung Stage
B1: S 01 | C1: S 02 | D1: S 03 | E1: S 04 | F1: S 05 | G1: S 06 | H1: S 07 | I1: S 08 | J1: S 09
A2: Jakob | B2: =SUMIF(Spieler_Teams!$A:$A,$A2,Spieler_Teams!C:C) -> 71 | C2: =SUMIF(Spieler_Teams!$A:$A,$A2,Spieler_Teams!D:D) -> 49 | D2: =SUMIF(Spieler_Teams!$A:$A,$A2,Spieler_Teams!E:E) -> 70 | E2: =SUMIF(Spieler_Teams!$A:$A,$A2,Spieler_Teams!F:F) -> 0 | F2: =SUMIF(Spieler_Teams!$A:$A,$A2,Spieler_Teams!G:G) -> 15 | G2: =SUMIF(Spieler_Teams!$A:$A,$A2,Spieler_Teams!H:H) -> 72 | H2: =SUMIF(Spieler_Teams!$A:$A,$A2,Spieler_Teams!I:I) -> 30 | I2: =SUMIF(Spieler_Teams!$A:$A,$A2,Spieler_Teams!J:J) -> 31 | J2: =SUMIF(Spieler_Teams!$A:$A,$A2,Spieler_Teams!K:K) -> 35
A3: Cindy | B3: =SUMIF(Spieler_Teams!A:A,A3,Spieler_Teams!C:C) -> 67 | C3: =SUMIF(Spieler_Teams!$A:$A,$A3,Spieler_Teams!D:D) -> 78 | D3: =SUMIF(Spieler_Teams!$A:$A,$A3,Spieler_Teams!E:E) -> 73 | E3: =SUMIF(Spieler_Teams!$A:$A,$A3,Spieler_Teams!F:F) -> 0 | F3: =SUMIF(Spieler_Teams!$A:$A,$A3,Spieler_Teams!G:G) -> 0 | G3: =SUMIF(Spieler_Teams!$A:$A,$A3,Spieler_Teams!H:H) -> 79 | H3: =SUMIF(Spieler_Teams!$A:$A,$A3,Spieler_Teams!I:I) -> 7 | I3: =SUMIF(Spieler_Teams!$A:$A,$A3,Spieler_Teams!J:J) -> 8 | J3: =SUMIF(Spieler_Teams!$A:$A,$A3,Spieler_Teams!K:K) -> 55
A4: Conni K | B4: =SUMIF(Spieler_Teams!A:A,A4,Spieler_Teams!C:C) -> 66 | C4: =SUMIF(Spieler_Teams!$A:$A,$A4,Spieler_Teams!D:D) -> 62 | D4: =SUMIF(Spieler_Teams!$A:$A,$A4,Spieler_Teams!E:E) -> 90 | E4: =SUMIF(Spieler_Teams!$A:$A,$A4,Spieler_Teams!F:F) -> 29 | F4: =SUMIF(Spieler_Teams!$A:$A,$A4,Spieler_Teams!G:G) -> 19 | G4: =SUMIF(Spieler_Teams!$A:$A,$A4,Spieler_Teams!H:H) -> 80 | H4: =SUMIF(Spieler_Teams!$A:$A,$A4,Spieler_Teams!I:I) -> 40 | I4: =SUMIF(Spieler_Teams!$A:$A,$A4,Spieler_Teams!J:J) -> 30 | J4: =SUMIF(Spieler_Teams!$A:$A,$A4,Spieler_Teams!K:K) -> 12
A5: Chris | B5: =SUMIF(Spieler_Teams!A:A,A5,Spieler_Teams!C:C) -> 61 | C5: =SUMIF(Spieler_Teams!$A:$A,$A5,Spieler_Teams!D:D) -> 48 | D5: =SUMIF(Spieler_Teams!$A:$A,$A5,Spieler_Teams!E:E) -> 68 | E5: =SUMIF(Spieler_Teams!$A:$A,$A5,Spieler_Teams!F:F) -> 6 | F5: =SUMIF(Spieler_Teams!$A:$A,$A5,Spieler_Teams!G:G) -> 26 | G5: =SUMIF(Spieler_Teams!$A:$A,$A5,Spieler_Teams!H:H) -> 65 | H5: =SUMIF(Spieler_Teams!$A:$A,$A5,Spieler_Teams!I:I) -> 41 | I5: =SUMIF(Spieler_Teams!$A:$A,$A5,Spieler_Teams!J:J) -> 42 | J5: =SUMIF(Spieler_Teams!$A:$A,$A5,Spieler_Teams!K:K) -> 10
A6: Nora | B6: =SUMIF(Spieler_Teams!A:A,A6,Spieler_Teams!C:C) -> 57 | C6: =SUMIF(Spieler_Teams!$A:$A,$A6,Spieler_Teams!D:D) -> 45 | D6: =SUMIF(Spieler_Teams!$A:$A,$A6,Spieler_Teams!E:E) -> 64 | E6: =SUMIF(Spieler_Teams!$A:$A,$A6,Spieler_Teams!F:F) -> 0 | F6: =SUMIF(Spieler_Teams!$A:$A,$A6,Spieler_Teams!G:G) -> 11 | G6: =SUMIF(Spieler_Teams!$A:$A,$A6,Spieler_Teams!H:H) -> 63 | H6: =SUMIF(Spieler_Teams!$A:$A,$A6,Spieler_Teams!I:I) -> 16 | I6: =SUMIF(Spieler_Teams!$A:$A,$A6,Spieler_Teams!J:J) -> 18 | J6: =SUMIF(Spieler_Teams!$A:$A,$A6,Spieler_Teams!K:K) -> 35
A7: Lea | B7: =SUMIF(Spieler_Teams!A:A,A7,Spieler_Teams!C:C) -> 55 | C7: =SUMIF(Spieler_Teams!$A:$A,$A7,Spieler_Teams!D:D) -> 46 | D7: =SUMIF(Spieler_Teams!$A:$A,$A7,Spieler_Teams!E:E) -> 68 | E7: =SUMIF(Spieler_Teams!$A:$A,$A7,Spieler_Teams!F:F) -> 21 | F7: =SUMIF(Spieler_Teams!$A:$A,$A7,Spieler_Teams!G:G) -> 21 | G7: =SUMIF(Spieler_Teams!$A:$A,$A7,Spieler_Teams!H:H) -> 56 | H7: =SUMIF(Spieler_Teams!$A:$A,$A7,Spieler_Teams!I:I) -> 31 | I7: =SUMIF(Spieler_Teams!$A:$A,$A7,Spieler_Teams!J:J) -> 37 | J7: =SUMIF(Spieler_Teams!$A:$A,$A7,Spieler_Teams!K:K) -> 10
A8: Lanci | B8: =SUMIF(Spieler_Teams!A:A,A8,Spieler_Teams!C:C) -> 54 | C8: =SUMIF(Spieler_Teams!$A:$A,$A8,Spieler_Teams!D:D) -> 59 | D8: =SUMIF(Spieler_Teams!$A:$A,$A8,Spieler_Teams!E:E) -> 68 | E8: =SUMIF(Spieler_Teams!$A:$A,$A8,Spieler_Teams!F:F) -> 30 | F8: =SUMIF(Spieler_Teams!$A:$A,$A8,Spieler_Teams!G:G) -> 12 | G8: =SUMIF(Spieler_Teams!$A:$A,$A8,Spieler_Teams!H:H) -> 75 | H8: =SUMIF(Spieler_Teams!$A:$A,$A8,Spieler_Teams!I:I) -> 22 | I8: =SUMIF(Spieler_Teams!$A:$A,$A8,Spieler_Teams!J:J) -> 25 | J8: =SUMIF(Spieler_Teams!$A:$A,$A8,Spieler_Teams!K:K) -> 25
A9: Sebbo | B9: =SUMIF(Spieler_Teams!A:A,A9,Spieler_Teams!C:C) -> 53 | C9: =SUMIF(Spieler_Teams!$A:$A,$A9,Spieler_Teams!D:D) -> 77 | D9: =SUMIF(Spieler_Teams!$A:$A,$A9,Spieler_Teams!E:E) -> 76 | E9: =SUMIF(Spieler_Teams!$A:$A,$A9,Spieler_Teams!F:F) -> 10 | F9: =SUMIF(Spieler_Teams!$A:$A,$A9,Spieler_Teams!G:G) -> 14 | G9: =SUMIF(Spieler_Teams!$A:$A,$A9,Spieler_Teams!H:H) -> 66 | H9: =SUMIF(Spieler_Teams!$A:$A,$A9,Spieler_Teams!I:I) -> 26 | I9: =SUMIF(Spieler_Teams!$A:$A,$A9,Spieler_Teams!J:J) -> 37 | J9: =SUMIF(Spieler_Teams!$A:$A,$A9,Spieler_Teams!K:K) -> 35
A10: Bendix | B10: =SUMIF(Spieler_Teams!A:A,A10,Spieler_Teams!C:C) -> 53 | C10: =SUMIF(Spieler_Teams!$A:$A,$A10,Spieler_Teams!D:D) -> 35 | D10: =SUMIF(Spieler_Teams!$A:$A,$A10,Spieler_Teams!E:E) -> 59 | E10: =SUMIF(Spieler_Teams!$A:$A,$A10,Spieler_Teams!F:F) -> 2 | F10: =SUMIF(Spieler_Teams!$A:$A,$A10,Spieler_Teams!G:G) -> 25 | G10: =SUMIF(Spieler_Teams!$A:$A,$A10,Spieler_Teams!H:H) -> 60 | H10: =SUMIF(Spieler_Teams!$A:$A,$A10,Spieler_Teams!I:I) -> 45 | I10: =SUMIF(Spieler_Teams!$A:$A,$A10,Spieler_Teams!J:J) -> 50 | J10: =SUMIF(Spieler_Teams!$A:$A,$A10,Spieler_Teams!K:K) -> 10
A11: Till | B11: =SUMIF(Spieler_Teams!A:A,A11,Spieler_Teams!C:C) -> 52 | C11: =SUMIF(Spieler_Teams!$A:$A,$A11,Spieler_Teams!D:D) -> 55 | D11: =SUMIF(Spieler_Teams!$A:$A,$A11,Spieler_Teams!E:E) -> 75 | E11: =SUMIF(Spieler_Teams!$A:$A,$A11,Spieler_Teams!F:F) -> 25 | F11: =SUMIF(Spieler_Teams!$A:$A,$A11,Spieler_Teams!G:G) -> 18 | G11: =SUMIF(Spieler_Teams!$A:$A,$A11,Spieler_Teams!H:H) -> 63 | H11: =SUMIF(Spieler_Teams!$A:$A,$A11,Spieler_Teams!I:I) -> 38 | I11: =SUMIF(Spieler_Teams!$A:$A,$A11,Spieler_Teams!J:J) -> 32 | J11: =SUMIF(Spieler_Teams!$A:$A,$A11,Spieler_Teams!K:K) -> 30
A12: Reto | B12: =SUMIF(Spieler_Teams!A:A,A12,Spieler_Teams!C:C) -> 50 | C12: =SUMIF(Spieler_Teams!$A:$A,$A12,Spieler_Teams!D:D) -> 48 | D12: =SUMIF(Spieler_Teams!$A:$A,$A12,Spieler_Teams!E:E) -> 65 | E12: =SUMIF(Spieler_Teams!$A:$A,$A12,Spieler_Teams!F:F) -> 0 | F12: =SUMIF(Spieler_Teams!$A:$A,$A12,Spieler_Teams!G:G) -> 46 | G12: =SUMIF(Spieler_Teams!$A:$A,$A12,Spieler_Teams!H:H) -> 62 | H12: =SUMIF(Spieler_Teams!$A:$A,$A12,Spieler_Teams!I:I) -> 53 | I12: =SUMIF(Spieler_Teams!$A:$A,$A12,Spieler_Teams!J:J) -> 50 | J12: =SUMIF(Spieler_Teams!$A:$A,$A12,Spieler_Teams!K:K) -> 46
A13: Konsti | B13: =SUMIF(Spieler_Teams!A:A,A13,Spieler_Teams!C:C) -> 50 | C13: =SUMIF(Spieler_Teams!$A:$A,$A13,Spieler_Teams!D:D) -> 62 | D13: =SUMIF(Spieler_Teams!$A:$A,$A13,Spieler_Teams!E:E) -> 45 | E13: =SUMIF(Spieler_Teams!$A:$A,$A13,Spieler_Teams!F:F) -> 10 | F13: =SUMIF(Spieler_Teams!$A:$A,$A13,Spieler_Teams!G:G) -> 20 | G13: =SUMIF(Spieler_Teams!$A:$A,$A13,Spieler_Teams!H:H) -> 60 | H13: =SUMIF(Spieler_Teams!$A:$A,$A13,Spieler_Teams!I:I) -> 14 | I13: =SUMIF(Spieler_Teams!$A:$A,$A13,Spieler_Teams!J:J) -> 9 | J13: =SUMIF(Spieler_Teams!$A:$A,$A13,Spieler_Teams!K:K) -> 26
A14: Jule | B14: =SUMIF(Spieler_Teams!A:A,A14,Spieler_Teams!C:C) -> 40 | C14: =SUMIF(Spieler_Teams!$A:$A,$A14,Spieler_Teams!D:D) -> 53 | D14: =SUMIF(Spieler_Teams!$A:$A,$A14,Spieler_Teams!E:E) -> 73 | E14: =SUMIF(Spieler_Teams!$A:$A,$A14,Spieler_Teams!F:F) -> 10 | F14: =SUMIF(Spieler_Teams!$A:$A,$A14,Spieler_Teams!G:G) -> 31 | G14: =SUMIF(Spieler_Teams!$A:$A,$A14,Spieler_Teams!H:H) -> 54 | H14: =SUMIF(Spieler_Teams!$A:$A,$A14,Spieler_Teams!I:I) -> 28 | I14: =SUMIF(Spieler_Teams!$A:$A,$A14,Spieler_Teams!J:J) -> 24 | J14: =SUMIF(Spieler_Teams!$A:$A,$A14,Spieler_Teams!K:K) -> 14
... A18: Simi | B18: =SUMIF(Spieler_Teams!A:A,A18,Spieler_Teams!C:C) -> 25 | C18: =SUMIF(Spieler_Teams!$A:$A,$A18,Spieler_Teams!D:D) -> 47 | D18: =SUMIF(Spieler_Teams!$A:$A,$A18,Spieler_Teams!E:E) -> 58 | E18: =SUMIF(Spieler_Teams!$A:$A,$A18,Spieler_Teams!F:F) -> 27 | F18: =SUMIF(Spieler_Teams!$A:$A,$A18,Spieler_Teams!G:G) -> 48 | G18: =SUMIF(Spieler_Teams!$A:$A,$A18,Spieler_Teams!H:H) -> 51 | H18: =SUMIF(Spieler_Teams!$A:$A,$A18,Spieler_Teams!I:I) -> 33 | I18: =SUMIF(Spieler_Teams!$A:$A,$A18,Spieler_Teams!J:J) -> 40 | J18: =SUMIF(Spieler_Teams!$A:$A,$A18,Spieler_Teams!K:K) -> 41

Sheet Spieler_Teams
A1: Spieler | B1: Fahrer | C1: Stage01 | D1: Stage02 | E1: Stage03 | F1: Stage04 | G1: Stage05 | H1: Stage06 | I1: Stage07 | J1: Stage08 | K1: Stage09
A2: Reto | B2: =Startlist2026!D2 -> PogačarTadejUAE Team Emirates - XRG | C2: =SUMIF(Ergebnisse_Roh!C$2:C$21,$B2,Punktematrix!$B$2:$B$21) -> 17 | D2: =SUMIF(Ergebnisse_Roh!D$2:D$21,$B2,Punktematrix!$B$2:$B$21) -> 20 | E2: =SUMIF(Ergebnisse_Roh!E$2:E$21,$B2,Punktematrix!$B$2:$B$21) -> 30 | F2: =SUMIF(Ergebnisse_Roh!F$2:F$21,$B2,Punktematrix!$B$2:$B$21) -> 0 | G2: =SUMIF(Ergebnisse_Roh!G$2:G$21,$B2,Punktematrix!$B$2:$B$21) -> 0 | H2: =SUMIF(Ergebnisse_Roh!H$2:H$21,$B2,Punktematrix!$B$2:$B$21) -> 30 | I2: =SUMIF(Ergebnisse_Roh!I$2:I$21,$B2,Punktematrix!$B$2:$B$21) -> 5 | J2: =SUMIF(Ergebnisse_Roh!J$2:J$21,$B2,Punktematrix!$B$2:$B$21) -> 5 | K2: =SUMIF(Ergebnisse_Roh!K$2:K$21,$B2,Punktematrix!$B$2:$B$21) -> 10
A3: Reto | B3: =Startlist2026!D82 -> van der PoelMathieuAlpecin - Premier Tech | C3: =SUMIF(Ergebnisse_Roh!C$2:C$21,$B3,Punktematrix!$B$2:$B$21) -> 5 | D3: =SUMIF(Ergebnisse_Roh!D$2:D$21,$B3,Punktematrix!$B$2:$B$21) -> 0 | E3: =SUMIF(Ergebnisse_Roh!E$2:E$21,$B3,Punktematrix!$B$2:$B$21) -> 0 | F3: =SUMIF(Ergebnisse_Roh!F$2:F$21,$B3,Punktematrix!$B$2:$B$21) -> 0 | G3: =SUMIF(Ergebnisse_Roh!G$2:G$21,$B3,Punktematrix!$B$2:$B$21) -> 0 | H3: =SUMIF(Ergebnisse_Roh!H$2:H$21,$B3,Punktematrix!$B$2:$B$21) -> 0 | I3: =SUMIF(Ergebnisse_Roh!I$2:I$21,$B3,Punktematrix!$B$2:$B$21) -> 0 | J3: =SUMIF(Ergebnisse_Roh!J$2:J$21,$B3,Punktematrix!$B$2:$B$21) -> 1 | K3: =SUMIF(Ergebnisse_Roh!K$2:K$21,$B3,Punktematrix!$B$2:$B$21) -> 25
A4: Reto | B4: =Startlist2026!D58 -> MartinezLennyBahrain - Victorious | C4: =SUMIF(Ergebnisse_Roh!C$2:C$21,$B4,Punktematrix!$B$2:$B$21) -> 1 | D4: =SUMIF(Ergebnisse_Roh!D$2:D$21,$B4,Punktematrix!$B$2:$B$21) -> 7 | E4: =SUMIF(Ergebnisse_Roh!E$2:E$21,$B4,Punktematrix!$B$2:$B$21) -> 3 | F4: =SUMIF(Ergebnisse_Roh!F$2:F$21,$B4,Punktematrix!$B$2:$B$21) -> 0 | G4: =SUMIF(Ergebnisse_Roh!G$2:G$21,$B4,Punktematrix!$B$2:$B$21) -> 0 | H4: =SUMIF(Ergebnisse_Roh!H$2:H$21,$B4,Punktematrix!$B$2:$B$21) -> 6 | I4: =SUMIF(Ergebnisse_Roh!I$2:I$21,$B4,Punktematrix!$B$2:$B$21) -> 0 | J4: =SUMIF(Ergebnisse_Roh!J$2:J$21,$B4,Punktematrix!$B$2:$B$21) -> 0 | K4: =SUMIF(Ergebnisse_Roh!K$2:K$21,$B4,Punktematrix!$B$2:$B$21) -> 0
A5: Reto | B5: =Startlist2026!D16 -> KussSeppTeam Visma | Lease a Bike | C5: =SUMIF(Ergebnisse_Roh!C$2:C$21,$B5,Punktematrix!$B$2:$B$21) -> 0 | D5: =SUMIF(Ergebnisse_Roh!D$2:D$21,$B5,Punktematrix!$B$2:$B$21) -> 0 | E5: =SUMIF(Ergebnisse_Roh!E$2:E$21,$B5,Punktematrix!$B$2:$B$21) -> 0 | F5: =SUMIF(Ergebnisse_Roh!F$2:F$21,$B5,Punktematrix!$B$2:$B$21) -> 0 | G5: =SUMIF(Ergebnisse_Roh!G$2:G$21,$B5,Punktematrix!$B$2:$B$21) -> 0 | H5: =SUMIF(Ergebnisse_Roh!H$2:H$21,$B5,Punktematrix!$B$2:$B$21) -> 7 | I5: =SUMIF(Ergebnisse_Roh!I$2:I$21,$B5,Punktematrix!$B$2:$B$21) -> 0 | J5: =SUMIF(Ergebnisse_Roh!J$2:J$21,$B5,Punktematrix!$B$2:$B$21) -> 0 | K5: =SUMIF(Ergebnisse_Roh!K$2:K$21,$B5,Punktematrix!$B$2:$B$21) -> 0
A6: Reto | B6: =Startlist2026!D69 -> GannaFilippoNetcompany INEOS | C6: =SUMIF(Ergebnisse_Roh!C$2:C$21,$B6,Punktematrix!$B$2:$B$21) -> 20 | D6: =SUMIF(Ergebnisse_Roh!D$2:D$21,$B6,Punktematrix!$B$2:$B$21) -> 0 | E6: =SUMIF(Ergebnisse_Roh!E$2:E$21,$B6,Punktematrix!$B$2:$B$21) -> 0 | F6: =SUMIF(Ergebnisse_Roh!F$2:F$21,$B6,Punktematrix!$B$2:$B$21) -> 0 | G6: =SUMIF(Ergebnisse_Roh!G$2:G$21,$B6,Punktematrix!$B$2:$B$21) -> 0 | H6: =SUMIF(Ergebnisse_Roh!H$2:H$21,$B6,Punktematrix!$B$2:$B$21) -> 0 | I6: =SUMIF(Ergebnisse_Roh!I$2:I$21,$B6,Punktematrix!$B$2:$B$21) -> 0 | J6: =SUMIF(Ergebnisse_Roh!J$2:J$21,$B6,Punktematrix!$B$2:$B$21) -> 0 | K6: =SUMIF(Ergebnisse_Roh!K$2:K$21,$B6,Punktematrix!$B$2:$B$21) -> 11
A7: Reto | B7: =Startlist2026!D34 -> CarapazRichardEF Education - EasyPost | C7: =SUMIF(Ergebnisse_Roh!C$2:C$21,$B7,Punktematrix!$B$2:$B$21) -> 0 | D7: =SUMIF(Ergebnisse_Roh!D$2:D$21,$B7,Punktematrix!$B$2:$B$21) -> 2 | E7: =SUMIF(Ergebnisse_Roh!E$2:E$21,$B7,Punktematrix!$B$2:$B$21) -> 15 | F7: =SUMIF(Ergebnisse_Roh!F$2:F$21,$B7,Punktematrix!$B$2:$B$21) -> 0 | G7: =SUMIF(Ergebnisse_Roh!G$2:G$21,$B7,Punktematrix!$B$2:$B$21) -> 0 | H7: =SUMIF(Ergebnisse_Roh!H$2:H$21,$B7,Punktematrix!$B$2:$B$21) -> 0 | I7: =SUMIF(Ergebnisse_Roh!I$2:I$21,$B7,Punktematrix!$B$2:$B$21) -> 0 | J7: =SUMIF(Ergebnisse_Roh!J$2:J$21,$B7,Punktematrix!$B$2:$B$21) -> 0 | K7: =SUMIF(Ergebnisse_Roh!K$2:K$21,$B7,Punktematrix!$B$2:$B$21) -> 0
A8: Reto | B8: =Startlist2026!D42 -> SeixasPaulDecathlon CMA CGM Team | C8: =SUMIF(Ergebnisse_Roh!C$2:C$21,$B8,Punktematrix!$B$2:$B$21) -> 7 | D8: =SUMIF(Ergebnisse_Roh!D$2:D$21,$B8,Punktematrix!$B$2:$B$21) -> 8 | E8: =SUMIF(Ergebnisse_Roh!E$2:E$21,$B8,Punktematrix!$B$2:$B$21) -> 12 | F8: =SUMIF(Ergebnisse_Roh!F$2:F$21,$B8,Punktematrix!$B$2:$B$21) -> 0 | G8: =SUMIF(Ergebnisse_Roh!G$2:G$21,$B8,Punktematrix!$B$2:$B$21) -> 0 | H8: =SUMIF(Ergebnisse_Roh!H$2:H$21,$B8,Punktematrix!$B$2:$B$21) -> 11 | I8: =SUMIF(Ergebnisse_Roh!I$2:I$21,$B8,Punktematrix!$B$2:$B$21) -> 0 | J8: =SUMIF(Ergebnisse_Roh!J$2:J$21,$B8,Punktematrix!$B$2:$B$21) -> 0 | K8: =SUMIF(Ergebnisse_Roh!K$2:K$21,$B8,Punktematrix!$B$2:$B$21) -> 0
A9: Reto | B9: =Startlist2026!D53 -> KanterMaxXDS Astana Team | C9: =SUMIF(Ergebnisse_Roh!C$2:C$21,$B9,Punktematrix!$B$2:$B$21) -> 0 | D9: =SUMIF(Ergebnisse_Roh!D$2:D$21,$B9,Punktematrix!$B$2:$B$21) -> 0 | E9: =SUMIF(Ergebnisse_Roh!E$2:E$21,$B9,Punktematrix!$B$2:$B$21) -> 0 | F9: =SUMIF(Ergebnisse_Roh!F$2:F$21,$B9,Punktematrix!$B$2:$B$21) -> 0 | G9: =SUMIF(Ergebnisse_Roh!G$2:G$21,$B9,Punktematrix!$B$2:$B$21) -> 20 | H9: =SUMIF(Ergebnisse_Roh!H$2:H$21,$B9,Punktematrix!$B$2:$B$21) -> 0 | I9: =SUMIF(Ergebnisse_Roh!I$2:I$21,$B9,Punktematrix!$B$2:$B$21) -> 12 | J9: =SUMIF(Ergebnisse_Roh!J$2:J$21,$B9,Punktematrix!$B$2:$B$21) -> 7 | K9: =SUMIF(Ergebnisse_Roh!K$2:K$21,$B9,Punktematrix!$B$2:$B$21) -> 0
A10: Reto | B10: =Startlist2026!D86 -> PhilipsenJasperAlpecin - Premier Tech | C10: =SUMIF(Ergebnisse_Roh!C$2:C$21,$B10,Punktematrix!$B$2:$B$21) -> 0 | D10: =SUMIF(Ergebnisse_Roh!D$2:D$21,$B10,Punktematrix!$B$2:$B$21) -> 0 | E10: =SUMIF(Ergebnisse_Roh!E$2:E$21,$B10,Punktematrix!$B$2:$B$21) -> 0 | F10: =SUMIF(Ergebnisse_Roh!F$2:F$21,$B10,Punktematrix!$B$2:$B$21) -> 0 | G10: =SUMIF(Ergebnisse_Roh!G$2:G$21,$B10,Punktematrix!$B$2:$B$21) -> 11 | H10: =SUMIF(Ergebnisse_Roh!H$2:H$21,$B10,Punktematrix!$B$2:$B$21) -> 0 | I10: =SUMIF(Ergebnisse_Roh!I$2:I$21,$B10,Punktematrix!$B$2:$B$21) -> 11 | J10: =SUMIF(Ergebnisse_Roh!J$2:J$21,$B10,Punktematrix!$B$2:$B$21) -> 12 | K10: =SUMIF(Ergebnisse_Roh!K$2:K$21,$B10,Punktematrix!$B$2:$B$21) -> 0
A11: Reto | B11: =Startlist2026!D74 -> MerlierTimSoudal Quick-Step | C11: =SUMIF(Ergebnisse_Roh!C$2:C$21,$B11,Punktematrix!$B$2:$B$21) -> 0 | D11: =SUMIF(Ergebnisse_Roh!D$2:D$21,$B11,Punktematrix!$B$2:$B$21) -> 0 | E11: =SUMIF(Ergebnisse_Roh!E$2:E$21,$B11,Punktematrix!$B$2:$B$21) -> 0 | F11: =SUMIF(Ergebnisse_Roh!F$2:F$21,$B11,Punktematrix!$B$2:$B$21) -> 0 | G11: =SUMIF(Ergebnisse_Roh!G$2:G$21,$B11,Punktematrix!$B$2:$B$21) -> 15 | H11: =SUMIF(Ergebnisse_Roh!H$2:H$21,$B11,Punktematrix!$B$2:$B$21) -> 0 | I11: =SUMIF(Ergebnisse_Roh!I$2:I$21,$B11,Punktematrix!$B$2:$B$21) -> 25 | J11: =SUMIF(Ergebnisse_Roh!J$2:J$21,$B11,Punktematrix!$B$2:$B$21) -> 25 | K11: =SUMIF(Ergebnisse_Roh!K$2:K$21,$B11,Punktematrix!$B$2:$B$21) -> 0
A12: Reto | B12: =Startlist2026!D30 -> SkjelmoseMattiasLidl - Trek | C12: =SUMIF(Ergebnisse_Roh!C$2:C$21,$B12,Punktematrix!$B$2:$B$21) -> 0 | D12: =SUMIF(Ergebnisse_Roh!D$2:D$21,$B12,Punktematrix!$B$2:$B$21) -> 11 | E12: =SUMIF(Ergebnisse_Roh!E$2:E$21,$B12,Punktematrix!$B$2:$B$21) -> 5 | F12: =SUMIF(Ergebnisse_Roh!F$2:F$21,$B12,Punktematrix!$B$2:$B$21) -> 0 | G12: =SUMIF(Ergebnisse_Roh!G$2:G$21,$B12,Punktematrix!$B$2:$B$21) -> 0 | H12: =SUMIF(Ergebnisse_Roh!H$2:H$21,$B12,Punktematrix!$B$2:$B$21) -> 8 | I12: =SUMIF(Ergebnisse_Roh!I$2:I$21,$B12,Punktematrix!$B$2:$B$21) -> 0 | J12: =SUMIF(Ergebnisse_Roh!J$2:J$21,$B12,Punktematrix!$B$2:$B$21) -> 0 | K12: =SUMIF(Ergebnisse_Roh!K$2:K$21,$B12,Punktematrix!$B$2:$B$21) -> 0
A13: Reto | B13: =Startlist2026!E18 -> Red Bull - BORA - hansgrohe | C13: =SUMIF(Ergebnisse_Roh!C$2:C$21,$B13,Punktematrix!$B$2:$B$21) -> 0 | D13: =SUMIF(Ergebnisse_Roh!D$2:D$21,$B13,Punktematrix!$B$2:$B$21) -> 0 | E13: =SUMIF(Ergebnisse_Roh!E$2:E$21,$B13,Punktematrix!$B$2:$B$21) -> 0 | F13: =SUMIF(Ergebnisse_Roh!F$2:F$21,$B13,Punktematrix!$B$2:$B$21) -> 0 | G13: =SUMIF(Ergebnisse_Roh!G$2:G$21,$B13,Punktematrix!$B$2:$B$21) -> 0 | H13: =SUMIF(Ergebnisse_Roh!H$2:H$21,$B13,Punktematrix!$B$2:$B$21) -> 0 | I13: =SUMIF(Ergebnisse_Roh!I$2:I$21,$B13,Punktematrix!$B$2:$B$21) -> 0 | J13: =SUMIF(Ergebnisse_Roh!J$2:J$21,$B13,Punktematrix!$B$2:$B$21) -> 0 | K13: =SUMIF(Ergebnisse_Roh!K$2:K$21,$B13,Punktematrix!$B$2:$B$21) -> 0
A14: Nora | B14: =Startlist2026!D2 -> PogačarTadejUAE Team Emirates - XRG | C14: =SUMIF(Ergebnisse_Roh!C$2:C$21,$B14,Punktematrix!$B$2:$B$21) -> 17 | D14: =SUMIF(Ergebnisse_Roh!D$2:D$21,$B14,Punktematrix!$B$2:$B$21) -> 20 | E14: =SUMIF(Ergebnisse_Roh!E$2:E$21,$B14,Punktematrix!$B$2:$B$21) -> 30 | F14: =SUMIF(Ergebnisse_Roh!F$2:F$21,$B14,Punktematrix!$B$2:$B$21) -> 0 | G14: =SUMIF(Ergebnisse_Roh!G$2:G$21,$B14,Punktematrix!$B$2:$B$21) -> 0 | H14: =SUMIF(Ergebnisse_Roh!H$2:H$21,$B14,Punktematrix!$B$2:$B$21) -> 30 | I14: =SUMIF(Ergebnisse_Roh!I$2:I$21,$B14,Punktematrix!$B$2:$B$21) -> 5 | J14: =SUMIF(Ergebnisse_Roh!J$2:J$21,$B14,Punktematrix!$B$2:$B$21) -> 5 | K14: =SUMIF(Ergebnisse_Roh!K$2:K$21,$B14,Punktematrix!$B$2:$B$21) -> 10
A15: Nora | B15: =Startlist2026!D82 -> van der PoelMathieuAlpecin - Premier Tech | C15: =SUMIF(Ergebnisse_Roh!C$2:C$21,$B15,Punktematrix!$B$2:$B$21) -> 5 | D15: =SUMIF(Ergebnisse_Roh!D$2:D$21,$B15,Punktematrix!$B$2:$B$21) -> 0 | E15: =SUMIF(Ergebnisse_Roh!E$2:E$21,$B15,Punktematrix!$B$2:$B$21) -> 0 | F15: =SUMIF(Ergebnisse_Roh!F$2:F$21,$B15,Punktematrix!$B$2:$B$21) -> 0 | G15: =SUMIF(Ergebnisse_Roh!G$2:G$21,$B15,Punktematrix!$B$2:$B$21) -> 0 | H15: =SUMIF(Ergebnisse_Roh!H$2:H$21,$B15,Punktematrix!$B$2:$B$21) -> 0 | I15: =SUMIF(Ergebnisse_Roh!I$2:I$21,$B15,Punktematrix!$B$2:$B$21) -> 0 | J15: =SUMIF(Ergebnisse_Roh!J$2:J$21,$B15,Punktematrix!$B$2:$B$21) -> 1 | K15: =SUMIF(Ergebnisse_Roh!K$2:K$21,$B15,Punktematrix!$B$2:$B$21) -> 25
A16: Nora | B16: =Startlist2026!D86 -> PhilipsenJasperAlpecin - Premier Tech | C16: =SUMIF(Ergebnisse_Roh!C$2:C$21,$B16,Punktematrix!$B$2:$B$21) -> 0 | D16: =SUMIF(Ergebnisse_Roh!D$2:D$21,$B16,Punktematrix!$B$2:$B$21) -> 0 | E16: =SUMIF(Ergebnisse_Roh!E$2:E$21,$B16,Punktematrix!$B$2:$B$21) -> 0 | F16: =SUMIF(Ergebnisse_Roh!F$2:F$21,$B16,Punktematrix!$B$2:$B$21) -> 0 | G16: =SUMIF(Ergebnisse_Roh!G$2:G$21,$B16,Punktematrix!$B$2:$B$21) -> 11 | H16: =SUMIF(Ergebnisse_Roh!H$2:H$21,$B16,Punktematrix!$B$2:$B$21) -> 0 | I16: =SUMIF(Ergebnisse_Roh!I$2:I$21,$B16,Punktematrix!$B$2:$B$21) -> 11 | J16: =SUMIF(Ergebnisse_Roh!J$2:J$21,$B16,Punktematrix!$B$2:$B$21) -> 12 | K16: =SUMIF(Ergebnisse_Roh!K$2:K$21,$B16,Punktematrix!$B$2:$B$21) -> 0
A17: Nora | B17: =Startlist2026!D42 -> SeixasPaulDecathlon CMA CGM Team | C17: =SUMIF(Ergebnisse_Roh!C$2:C$21,$B17,Punktematrix!$B$2:$B$21) -> 7 | D17: =SUMIF(Ergebnisse_Roh!D$2:D$21,$B17,Punktematrix!$B$2:$B$21) -> 8 | E17: =SUMIF(Ergebnisse_Roh!E$2:E$21,$B17,Punktematrix!$B$2:$B$21) -> 12 | F17: =SUMIF(Ergebnisse_Roh!F$2:F$21,$B17,Punktematrix!$B$2:$B$21) -> 0 | G17: =SUMIF(Ergebnisse_Roh!G$2:G$21,$B17,Punktematrix!$B$2:$B$21) -> 0 | H17: =SUMIF(Ergebnisse_Roh!H$2:H$21,$B17,Punktematrix!$B$2:$B$21) -> 11 | I17: =SUMIF(Ergebnisse_Roh!I$2:I$21,$B17,Punktematrix!$B$2:$B$21) -> 0 | J17: =SUMIF(Ergebnisse_Roh!J$2:J$21,$B17,Punktematrix!$B$2:$B$21) -> 0 | K17: =SUMIF(Ergebnisse_Roh!K$2:K$21,$B17,Punktematrix!$B$2:$B$21) -> 0
A18: Nora | B18: =Startlist2026!E2 -> UAE Team Emirates - XRG | C18: =SUMIF(Ergebnisse_Roh!C$2:C$21,$B18,Punktematrix!$B$2:$B$21) -> 0 | D18: =SUMIF(Ergebnisse_Roh!D$2:D$21,$B18,Punktematrix!$B$2:$B$21) -> 2 | E18: =SUMIF(Ergebnisse_Roh!E$2:E$21,$B18,Punktematrix!$B$2:$B$21) -> 2 | F18: =SUMIF(Ergebnisse_Roh!F$2:F$21,$B18,Punktematrix!$B$2:$B$21) -> 0 | G18: =SUMIF(Ergebnisse_Roh!G$2:G$21,$B18,Punktematrix!$B$2:$B$21) -> 0 | H18: =SUMIF(Ergebnisse_Roh!H$2:H$21,$B18,Punktematrix!$B$2:$B$21) -> 2 | I18: =SUMIF(Ergebnisse_Roh!I$2:I$21,$B18,Punktematrix!$B$2:$B$21) -> 0 | J18: =SUMIF(Ergebnisse_Roh!J$2:J$21,$B18,Punktematrix!$B$2:$B$21) -> 0 | K18: =SUMIF(Ergebnisse_Roh!K$2:K$21,$B18,Punktematrix!$B$2:$B$21) -> 0
A19: Nora | B19: =Startlist2026!D9 -> YatesAdamUAE Team Emirates - XRG | C19: =SUMIF(Ergebnisse_Roh!C$2:C$21,$B19,Punktematrix!$B$2:$B$21) -> 0 | D19: =SUMIF(Ergebnisse_Roh!D$2:D$21,$B19,Punktematrix!$B$2:$B$21) -> 0 | E19: =SUMIF(Ergebnisse_Roh!E$2:E$21,$B19,Punktematrix!$B$2:$B$21) -> 0 | F19: =SUMIF(Ergebnisse_Roh!F$2:F$21,$B19,Punktematrix!$B$2:$B$21) -> 0 | G19: =SUMIF(Ergebnisse_Roh!G$2:G$21,$B19,Punktematrix!$B$2:$B$21) -> 0 | H19: =SUMIF(Ergebnisse_Roh!H$2:H$21,$B19,Punktematrix!$B$2:$B$21) -> 0 | I19: =SUMIF(Ergebnisse_Roh!I$2:I$21,$B19,Punktematrix!$B$2:$B$21) -> 0 | J19: =SUMIF(Ergebnisse_Roh!J$2:J$21,$B19,Punktematrix!$B$2:$B$21) -> 0 | K19: =SUMIF(Ergebnisse_Roh!K$2:K$21,$B19,Punktematrix!$B$2:$B$21) -> 0
A20: Nora | B20: =Startlist2026!D122 -> De LieArnaudLotto Intermarché | C20: =SUMIF(Ergebnisse_Roh!C$2:C$21,$B20,Punktematrix!$B$2:$B$21) -> 0 | D20: =SUMIF(Ergebnisse_Roh!D$2:D$21,$B20,Punktematrix!$B$2:$B$21) -> 0 | E20: =SUMIF(Ergebnisse_Roh!E$2:E$21,$B20,Punktematrix!$B$2:$B$21) -> 0 | F20: =SUMIF(Ergebnisse_Roh!F$2:F$21,$B20,Punktematrix!$B$2:$B$21) -> 0 | G20: =SUMIF(Ergebnisse_Roh!G$2:G$21,$B20,Punktematrix!$B$2:$B$21) -> 0 | H20: =SUMIF(Ergebnisse_Roh!H$2:H$21,$B20,Punktematrix!$B$2:$B$21) -> 0 | I20: =SUMIF(Ergebnisse_Roh!I$2:I$21,$B20,Punktematrix!$B$2:$B$21) -> 0 | J20: =SUMIF(Ergebnisse_Roh!J$2:J$21,$B20,Punktematrix!$B$2:$B$21) -> 0 | K20: =SUMIF(Ergebnisse_Roh!K$2:K$21,$B20,Punktematrix!$B$2:$B$21) -> 0
A21: Nora | B21: =Startlist2026!D13 -> CampenaertsVictorTeam Visma | Lease a Bike | C21: =SUMIF(Ergebnisse_Roh!C$2:C$21,$B21,Punktematrix!$B$2:$B$21) -> 0 | D21: =SUMIF(Ergebnisse_Roh!D$2:D$21,$B21,Punktematrix!$B$2:$B$21) -> 0 | E21: =SUMIF(Ergebnisse_Roh!E$2:E$21,$B21,Punktematrix!$B$2:$B$21) -> 0 | F21: =SUMIF(Ergebnisse_Roh!F$2:F$21,$B21,Punktematrix!$B$2:$B$21) -> 0 | G21: =SUMIF(Ergebnisse_Roh!G$2:G$21,$B21,Punktematrix!$B$2:$B$21) -> 0 | H21: =SUMIF(Ergebnisse_Roh!H$2:H$21,$B21,Punktematrix!$B$2:$B$21) -> 0 | I21: =SUMIF(Ergebnisse_Roh!I$2:I$21,$B21,Punktematrix!$B$2:$B$21) -> 0 | J21: =SUMIF(Ergebnisse_Roh!J$2:J$21,$B21,Punktematrix!$B$2:$B$21) -> 0 | K21: =SUMIF(Ergebnisse_Roh!K$2:K$21,$B21,Punktematrix!$B$2:$B$21) -> 0
A22: Nora | B22: =Startlist2026!D10 -> VingegaardJonasTeam Visma | Lease a Bike | C22: =SUMIF(Ergebnisse_Roh!C$2:C$21,$B22,Punktematrix!$B$2:$B$21) -> 28 | D22: =SUMIF(Ergebnisse_Roh!D$2:D$21,$B22,Punktematrix!$B$2:$B$21) -> 15 | E22: =SUMIF(Ergebnisse_Roh!E$2:E$21,$B22,Punktematrix!$B$2:$B$21) -> 20 | F22: =SUMIF(Ergebnisse_Roh!F$2:F$21,$B22,Punktematrix!$B$2:$B$21) -> 0 | G22: =SUMIF(Ergebnisse_Roh!G$2:G$21,$B22,Punktematrix!$B$2:$B$21) -> 0 | H22: =SUMIF(Ergebnisse_Roh!H$2:H$21,$B22,Punktematrix!$B$2:$B$21) -> 20 | I22: =SUMIF(Ergebnisse_Roh!I$2:I$21,$B22,Punktematrix!$B$2:$B$21) -> 0 | J22: =SUMIF(Ergebnisse_Roh!J$2:J$21,$B22,Punktematrix!$B$2:$B$21) -> 0 | K22: =SUMIF(Ergebnisse_Roh!K$2:K$21,$B22,Punktematrix!$B$2:$B$21) -> 0
A23: Nora | B23: =Startlist2026!D67 -> ArensmanThymenNetcompany INEOS | C23: =SUMIF(Ergebnisse_Roh!C$2:C$21,$B23,Punktematrix!$B$2:$B$21) -> 0 | D23: =SUMIF(Ergebnisse_Roh!D$2:D$21,$B23,Punktematrix!$B$2:$B$21) -> 0 | E23: =SUMIF(Ergebnisse_Roh!E$2:E$21,$B23,Punktematrix!$B$2:$B$21) -> 0 | F23: =SUMIF(Ergebnisse_Roh!F$2:F$21,$B23,Punktematrix!$B$2:$B$21) -> 0 | G23: =SUMIF(Ergebnisse_Roh!G$2:G$21,$B23,Punktematrix!$B$2:$B$21) -> 0 | H23: =SUMIF(Ergebnisse_Roh!H$2:H$21,$B23,Punktematrix!$B$2:$B$21) -> 0 | I23: =SUMIF(Ergebnisse_Roh!I$2:I$21,$B23,Punktematrix!$B$2:$B$21) -> 0 | J23: =SUMIF(Ergebnisse_Roh!J$2:J$21,$B23,Punktematrix!$B$2:$B$21) -> 0 | K23: =SUMIF(Ergebnisse_Roh!K$2:K$21,$B23,Punktematrix!$B$2:$B$21) -> 0
A24: Chrysli | B24: =Startlist2026!D22 -> LipowitzFlorianRed Bull - BORA - hansgrohe | C24: =SUMIF(Ergebnisse_Roh!C$2:C$21,$B24,Punktematrix!$B$2:$B$21) -> 8 | D24: =SUMIF(Ergebnisse_Roh!D$2:D$21,$B24,Punktematrix!$B$2:$B$21) -> 0 | E24: =SUMIF(Ergebnisse_Roh!E$2:E$21,$B24,Punktematrix!$B$2:$B$21) -> 9 | F24: =SUMIF(Ergebnisse_Roh!F$2:F$21,$B24,Punktematrix!$B$2:$B$21) -> 0 | G24: =SUMIF(Ergebnisse_Roh!G$2:G$21,$B24,Punktematrix!$B$2:$B$21) -> 0 | H24: =SUMIF(Ergebnisse_Roh!H$2:H$21,$B24,Punktematrix!$B$2:$B$21) -> 10 | I24: =SUMIF(Ergebnisse_Roh!I$2:I$21,$B24,Punktematrix!$B$2:$B$21) -> 0 | J24: =SUMIF(Ergebnisse_Roh!J$2:J$21,$B24,Punktematrix!$B$2:$B$21) -> 0 | K24: =SUMIF(Ergebnisse_Roh!K$2:K$21,$B24,Punktematrix!$B$2:$B$21) -> 0
A25: Chrysli | B25: =Startlist2026!D42 -> SeixasPaulDecathlon CMA CGM Team | C25: =SUMIF(Ergebnisse_Roh!C$2:C$21,$B25,Punktematrix!$B$2:$B$21) -> 7 | D25: =SUMIF(Ergebnisse_Roh!D$2:D$21,$B25,Punktematrix!$B$2:$B$21) -> 8 | E25: =SUMIF(Ergebnisse_Roh!E$2:E$21,$B25,Punktematrix!$B$2:$B$21) -> 12 | F25: =SUMIF(Ergebnisse_Roh!F$2:F$21,$B25,Punktematrix!$B$2:$B$21) -> 0 | G25: =SUMIF(Ergebnisse_Roh!G$2:G$21,$B25,Punktematrix!$B$2:$B$21) -> 0 | H25: =SUMIF(Ergebnisse_Roh!H$2:H$21,$B25,Punktematrix!$B$2:$B$21) -> 11 | I25: =SUMIF(Ergebnisse_Roh!I$2:I$21,$B25,Punktematrix!$B$2:$B$21) -> 0 | J25: =SUMIF(Ergebnisse_Roh!J$2:J$21,$B25,Punktematrix!$B$2:$B$21) -> 0 | K25: =SUMIF(Ergebnisse_Roh!K$2:K$21,$B25,Punktematrix!$B$2:$B$21) -> 0
A26: Chrysli | B26: =Startlist2026!D5 -> McNultyBrandonUAE Team Emirates - XRG | C26: =SUMIF(Ergebnisse_Roh!C$2:C$21,$B26,Punktematrix!$B$2:$B$21) -> 0 | D26: =SUMIF(Ergebnisse_Roh!D$2:D$21,$B26,Punktematrix!$B$2:$B$21) -> 0 | E26: =SUMIF(Ergebnisse_Roh!E$2:E$21,$B26,Punktematrix!$B$2:$B$21) -> 0 | F26: =SUMIF(Ergebnisse_Roh!F$2:F$21,$B26,Punktematrix!$B$2:$B$21) -> 0 | G26: =SUMIF(Ergebnisse_Roh!G$2:G$21,$B26,Punktematrix!$B$2:$B$21) -> 0 | H26: =SUMIF(Ergebnisse_Roh!H$2:H$21,$B26,Punktematrix!$B$2:$B$21) -> 0 | I26: =SUMIF(Ergebnisse_Roh!I$2:I$21,$B26,Punktematrix!$B$2:$B$21) -> 0 | J26: =SUMIF(Ergebnisse_Roh!J$2:J$21,$B26,Punktematrix!$B$2:$B$21) -> 0 | K26: =SUMIF(Ergebnisse_Roh!K$2:K$21,$B26,Punktematrix!$B$2:$B$21) -> 0
A27: Chrysli | B27: =Startlist2026!D24 -> van DijkeTimRed Bull - BORA - hansgrohe | C27: =SUMIF(Ergebnisse_Roh!C$2:C$21,$B27,Punktematrix!$B$2:$B$21) -> 0 | D27: =SUMIF(Ergebnisse_Roh!D$2:D$21,$B27,Punktematrix!$B$2:$B$21) -> 0 | E27: =SUMIF(Ergebnisse_Roh!E$2:E$21,$B27,Punktematrix!$B$2:$B$21) -> 0 | F27: =SUMIF(Ergebnisse_Roh!F$2:F$21,$B27,Punktematrix!$B$2:$B$21) -> 0 | G27: =SUMIF(Ergebnisse_Roh!G$2:G$21,$B27,Punktematrix!$B$2:$B$21) -> 0 | H27: =SUMIF(Ergebnisse_Roh!H$2:H$21,$B27,Punktematrix!$B$2:$B$21) -> 0 | I27: =SUMIF(Ergebnisse_Roh!I$2:I$21,$B27,Punktematrix!$B$2:$B$21) -> 0 | J27: =SUMIF(Ergebnisse_Roh!J$2:J$21,$B27,Punktematrix!$B$2:$B$21) -> 0 | K27: =SUMIF(Ergebnisse_Roh!K$2:K$21,$B27,Punktematrix!$B$2:$B$21) -> 0
A28: Chrysli | B28: =Startlist2026!D114 -> UijtdebroeksCianMovistar Team | C28: =SUMIF(Ergebnisse_Roh!C$2:C$21,$B28,Punktematrix!$B$2:$B$21) -> 0 | D28: =SUMIF(Ergebnisse_Roh!D$2:D$21,$B28,Punktematrix!$B$2:$B$21) -> 0 | E28: =SUMIF(Ergebnisse_Roh!E$2:E$21,$B28,Punktematrix!$B$2:$B$21) -> 0 | F28: =SUMIF(Ergebnisse_Roh!F$2:F$21,$B28,Punktematrix!$B$2:$B$21) -> 0 | G28: =SUMIF(Ergebnisse_Roh!G$2:G$21,$B28,Punktematrix!$B$2:$B$21) -> 0 | H28: =SUMIF(Ergebnisse_Roh!H$2:H$21,$B28,Punktematrix!$B$2:$B$21) -> 0 | I28: =SUMIF(Ergebnisse_Roh!I$2:I$21,$B28,Punktematrix!$B$2:$B$21) -> 0 | J28: =SUMIF(Ergebnisse_Roh!J$2:J$21,$B28,Punktematrix!$B$2:$B$21) -> 0 | K28: =SUMIF(Ergebnisse_Roh!K$2:K$21,$B28,Punktematrix!$B$2:$B$21) -> 0
A29: Chrysli | B29: =Startlist2026!D83 -> DebruyneRamsesAlpecin - Premier Tech | C29: =SUMIF(Ergebnisse_Roh!C$2:C$21,$B29,Punktematrix!$B$2:$B$21) -> 0 | D29: =SUMIF(Ergebnisse_Roh!D$2:D$21,$B29,Punktematrix!$B$2:$B$21) -> 0 | E29: =SUMIF(Ergebnisse_Roh!E$2:E$21,$B29,Punktematrix!$B$2:$B$21) -> 0 | F29: =SUMIF(Ergebnisse_Roh!F$2:F$21,$B29,Punktematrix!$B$2:$B$21) -> 11 | G29: =SUMIF(Ergebnisse_Roh!G$2:G$21,$B29,Punktematrix!$B$2:$B$21) -> 0 | H29: =SUMIF(Ergebnisse_Roh!H$2:H$21,$B29,Punktematrix!$B$2:$B$21) -> 0 | I29: =SUMIF(Ergebnisse_Roh!I$2:I$21,$B29,Punktematrix!$B$2:$B$21) -> 0 | J29: =SUMIF(Ergebnisse_Roh!J$2:J$21,$B29,Punktematrix!$B$2:$B$21) -> 0 | K29: =SUMIF(Ergebnisse_Roh!K$2:K$21,$B29,Punktematrix!$B$2:$B$21) -> 0
A30: Chrysli | B30: =Startlist2026!D3 -> del ToroIsaacUAE Team Emirates - XRG | C30: =SUMIF(Ergebnisse_Roh!C$2:C$21,$B30,Punktematrix!$B$2:$B$21) -> 10 | D30: =SUMIF(Ergebnisse_Roh!D$2:D$21,$B30,Punktematrix!$B$2:$B$21) -> 29 | E30: =SUMIF(Ergebnisse_Roh!E$2:E$21,$B30,Punktematrix!$B$2:$B$21) -> 10 | F30: =SUMIF(Ergebnisse_Roh!F$2:F$21,$B30,Punktematrix!$B$2:$B$21) -> 0 | G30: =SUMIF(Ergebnisse_Roh!G$2:G$21,$B30,Punktematrix!$B$2:$B$21) -> 0 | H30: =SUMIF(Ergebnisse_Roh!H$2:H$21,$B30,Punktematrix!$B$2:$B$21) -> 17 | I30: =SUMIF(Ergebnisse_Roh!I$2:I$21,$B30,Punktematrix!$B$2:$B$21) -> 2 | J30: =SUMIF(Ergebnisse_Roh!J$2:J$21,$B30,Punktematrix!$B$2:$B$21) -> 2 | K30: =SUMIF(Ergebnisse_Roh!K$2:K$21,$B30,Punktematrix!$B$2:$B$21) -> 5
A31: Chrysli | B31: =Startlist2026!D59 -> BauhausPhilBahrain - Victorious | C31: =SUMIF(Ergebnisse_Roh!C$2:C$21,$B31,Punktematrix!$B$2:$B$21) -> 0 | D31: =SUMIF(Ergebnisse_Roh!D$2:D$21,$B31,Punktematrix!$B$2:$B$21) -> 0 | E31: =SUMIF(Ergebnisse_Roh!E$2:E$21,$B31,Punktematrix!$B$2:$B$21) -> 0 | F31: =SUMIF(Ergebnisse_Roh!F$2:F$21,$B31,Punktematrix!$B$2:$B$21) -> 0 | G31: =SUMIF(Ergebnisse_Roh!G$2:G$21,$B31,Punktematrix!$B$2:$B$21) -> 0 | H31: =SUMIF(Ergebnisse_Roh!H$2:H$21,$B31,Punktematrix!$B$2:$B$21) -> 0 | I31: =SUMIF(Ergebnisse_Roh!I$2:I$21,$B31,Punktematrix!$B$2:$B$21) -> 10 | J31: =SUMIF(Ergebnisse_Roh!J$2:J$21,$B31,Punktematrix!$B$2:$B$21) -> 0 | K31: =SUMIF(Ergebnisse_Roh!K$2:K$21,$B31,Punktematrix!$B$2:$B$21) -> 0
A32: Chrysli | B32: =Startlist2026!D6 -> PolittNilsUAE Team Emirates - XRG | C32: =SUMIF(Ergebnisse_Roh!C$2:C$21,$B32,Punktematrix!$B$2:$B$21) -> 0 | D32: =SUMIF(Ergebnisse_Roh!D$2:D$21,$B32,Punktematrix!$B$2:$B$21) -> 0 | E32: =SUMIF(Ergebnisse_Roh!E$2:E$21,$B32,Punktematrix!$B$2:$B$21) -> 0 | F32: =SUMIF(Ergebnisse_Roh!F$2:F$21,$B32,Punktematrix!$B$2:$B$21) -> 0 | G32: =SUMIF(Ergebnisse_Roh!G$2:G$21,$B32,Punktematrix!$B$2:$B$21) -> 0 | H32: =SUMIF(Ergebnisse_Roh!H$2:H$21,$B32,Punktematrix!$B$2:$B$21) -> 0 | I32: =SUMIF(Ergebnisse_Roh!I$2:I$21,$B32,Punktematrix!$B$2:$B$21) -> 0 | J32: =SUMIF(Ergebnisse_Roh!J$2:J$21,$B32,Punktematrix!$B$2:$B$21) -> 0 | K32: =SUMIF(Ergebnisse_Roh!K$2:K$21,$B32,Punktematrix!$B$2:$B$21) -> 0
A33: Chrysli | B33: =Startlist2026!D17 -> PiganzoliDavideTeam Visma | Lease a Bike | C33: =SUMIF(Ergebnisse_Roh!C$2:C$21,$B33,Punktematrix!$B$2:$B$21) -> 9 | D33: =SUMIF(Ergebnisse_Roh!D$2:D$21,$B33,Punktematrix!$B$2:$B$21) -> 0 | E33: =SUMIF(Ergebnisse_Roh!E$2:E$21,$B33,Punktematrix!$B$2:$B$21) -> 0 | F33: =SUMIF(Ergebnisse_Roh!F$2:F$21,$B33,Punktematrix!$B$2:$B$21) -> 0 | G33: =SUMIF(Ergebnisse_Roh!G$2:G$21,$B33,Punktematrix!$B$2:$B$21) -> 0 | H33: =SUMIF(Ergebnisse_Roh!H$2:H$21,$B33,Punktematrix!$B$2:$B$21) -> 0 | I33: =SUMIF(Ergebnisse_Roh!I$2:I$21,$B33,Punktematrix!$B$2:$B$21) -> 0 | J33: =SUMIF(Ergebnisse_Roh!J$2:J$21,$B33,Punktematrix!$B$2:$B$21) -> 0 | K33: =SUMIF(Ergebnisse_Roh!K$2:K$21,$B33,Punktematrix!$B$2:$B$21) -> 0
A34: Chrysli | B34: =Startlist2026!D86 -> PhilipsenJasperAlpecin - Premier Tech | C34: =SUMIF(Ergebnisse_Roh!C$2:C$21,$B34,Punktematrix!$B$2:$B$21) -> 0 | D34: =SUMIF(Ergebnisse_Roh!D$2:D$21,$B34,Punktematrix!$B$2:$B$21) -> 0 | E34: =SUMIF(Ergebnisse_Roh!E$2:E$21,$B34,Punktematrix!$B$2:$B$21) -> 0 | F34: =SUMIF(Ergebnisse_Roh!F$2:F$21,$B34,Punktematrix!$B$2:$B$21) -> 0 | G34: =SUMIF(Ergebnisse_Roh!G$2:G$21,$B34,Punktematrix!$B$2:$B$21) -> 11 | H34: =SUMIF(Ergebnisse_Roh!H$2:H$21,$B34,Punktematrix!$B$2:$B$21) -> 0 | I34: =SUMIF(Ergebnisse_Roh!I$2:I$21,$B34,Punktematrix!$B$2:$B$21) -> 11 | J34: =SUMIF(Ergebnisse_Roh!J$2:J$21,$B34,Punktematrix!$B$2:$B$21) -> 12 | K34: =SUMIF(Ergebnisse_Roh!K$2:K$21,$B34,Punktematrix!$B$2:$B$21) -> 0
A35: Chrysli | B35: van den BergJuliusTeam Picnic PostNL | C35: =SUMIF(Ergebnisse_Roh!C$2:C$21,$B35,Punktematrix!$B$2:$B$21) -> 0 | D35: =SUMIF(Ergebnisse_Roh!D$2:D$21,$B35,Punktematrix!$B$2:$B$21) -> 0 | E35: =SUMIF(Ergebnisse_Roh!E$2:E$21,$B35,Punktematrix!$B$2:$B$21) -> 0 | F35: =SUMIF(Ergebnisse_Roh!F$2:F$21,$B35,Punktematrix!$B$2:$B$21) -> 0 | G35: =SUMIF(Ergebnisse_Roh!G$2:G$21,$B35,Punktematrix!$B$2:$B$21) -> 0 | H35: =SUMIF(Ergebnisse_Roh!H$2:H$21,$B35,Punktematrix!$B$2:$B$21) -> 0 | I35: =SUMIF(Ergebnisse_Roh!I$2:I$21,$B35,Punktematrix!$B$2:$B$21) -> 0 | J35: =SUMIF(Ergebnisse_Roh!J$2:J$21,$B35,Punktematrix!$B$2:$B$21) -> 0 | K35: =SUMIF(Ergebnisse_Roh!K$2:K$21,$B35,Punktematrix!$B$2:$B$21) -> 0
A36: Chrysli | B36: VermeerschFlorianUAE Team Emirates - XRG | C36: =SUMIF(Ergebnisse_Roh!C$2:C$21,$B36,Punktematrix!$B$2:$B$21) -> 0 | D36: =SUMIF(Ergebnisse_Roh!D$2:D$21,$B36,Punktematrix!$B$2:$B$21) -> 0 | E36: =SUMIF(Ergebnisse_Roh!E$2:E$21,$B36,Punktematrix!$B$2:$B$21) -> 0 | F36: =SUMIF(Ergebnisse_Roh!F$2:F$21,$B36,Punktematrix!$B$2:$B$21) -> 0 | G36: =SUMIF(Ergebnisse_Roh!G$2:G$21,$B36,Punktematrix!$B$2:$B$21) -> 0 | H36: =SUMIF(Ergebnisse_Roh!H$2:H$21,$B36,Punktematrix!$B$2:$B$21) -> 0 | I36: =SUMIF(Ergebnisse_Roh!I$2:I$21,$B36,Punktematrix!$B$2:$B$21) -> 0 | J36: =SUMIF(Ergebnisse_Roh!J$2:J$21,$B36,Punktematrix!$B$2:$B$21) -> 0 | K36: =SUMIF(Ergebnisse_Roh!K$2:K$21,$B36,Punktematrix!$B$2:$B$21) -> 0
A37: Chrysli | B37: O'ConnorBenTeam Jayco AlUla | C37: =SUMIF(Ergebnisse_Roh!C$2:C$21,$B37,Punktematrix!$B$2:$B$21) -> 0 | D37: =SUMIF(Ergebnisse_Roh!D$2:D$21,$B37,Punktematrix!$B$2:$B$21) -> 0 | E37: =SUMIF(Ergebnisse_Roh!E$2:E$21,$B37,Punktematrix!$B$2:$B$21) -> 0 | F37: =SUMIF(Ergebnisse_Roh!F$2:F$21,$B37,Punktematrix!$B$2:$B$21) -> 0 | G37: =SUMIF(Ergebnisse_Roh!G$2:G$21,$B37,Punktematrix!$B$2:$B$21) -> 0 | H37: =SUMIF(Ergebnisse_Roh!H$2:H$21,$B37,Punktematrix!$B$2:$B$21) -> 0 | I37: =SUMIF(Ergebnisse_Roh!I$2:I$21,$B37,Punktematrix!$B$2:$B$21) -> 0 | J37: =SUMIF(Ergebnisse_Roh!J$2:J$21,$B37,Punktematrix!$B$2:$B$21) -> 0 | K37: =SUMIF(Ergebnisse_Roh!K$2:K$21,$B37,Punktematrix!$B$2:$B$21) -> 0
A38: Chrysli | B38: JorgensonMatteoTeam Visma | Lease a Bike | C38: =SUMIF(Ergebnisse_Roh!C$2:C$21,$B38,Punktematrix!$B$2:$B$21) -> 0 | D38: =SUMIF(Ergebnisse_Roh!D$2:D$21,$B38,Punktematrix!$B$2:$B$21) -> 0 | E38: =SUMIF(Ergebnisse_Roh!E$2:E$21,$B38,Punktematrix!$B$2:$B$21) -> 0 | F38: =SUMIF(Ergebnisse_Roh!F$2:F$21,$B38,Punktematrix!$B$2:$B$21) -> 0 | G38: =SUMIF(Ergebnisse_Roh!G$2:G$21,$B38,Punktematrix!$B$2:$B$21) -> 0 | H38: =SUMIF(Ergebnisse_Roh!H$2:H$21,$B38,Punktematrix!$B$2:$B$21) -> 0 | I38: =SUMIF(Ergebnisse_Roh!I$2:I$21,$B38,Punktematrix!$B$2:$B$21) -> 0 | J38: =SUMIF(Ergebnisse_Roh!J$2:J$21,$B38,Punktematrix!$B$2:$B$21) -> 0 | K38: =SUMIF(Ergebnisse_Roh!K$2:K$21,$B38,Punktematrix!$B$2:$B$21) -> 0
A39: Chrysli | B39: Decathlon CMA CGM Team | C39: =SUMIF(Ergebnisse_Roh!C$2:C$21,$B39,Punktematrix!$B$2:$B$21) -> 0 | D39: =SUMIF(Ergebnisse_Roh!D$2:D$21,$B39,Punktematrix!$B$2:$B$21) -> 0 | E39: =SUMIF(Ergebnisse_Roh!E$2:E$21,$B39,Punktematrix!$B$2:$B$21) -> 0 | F39: =SUMIF(Ergebnisse_Roh!F$2:F$21,$B39,Punktematrix!$B$2:$B$21) -> 0 | G39: =SUMIF(Ergebnisse_Roh!G$2:G$21,$B39,Punktematrix!$B$2:$B$21) -> 0 | H39: =SUMIF(Ergebnisse_Roh!H$2:H$21,$B39,Punktematrix!$B$2:$B$21) -> 0 | I39: =SUMIF(Ergebnisse_Roh!I$2:I$21,$B39,Punktematrix!$B$2:$B$21) -> 0 | J39: =SUMIF(Ergebnisse_Roh!J$2:J$21,$B39,Punktematrix!$B$2:$B$21) -> 0 | K39: =SUMIF(Ergebnisse_Roh!K$2:K$21,$B39,Punktematrix!$B$2:$B$21) -> 0
A40: Rikki | B40: PogačarTadejUAE Team Emirates - XRG | C40: =SUMIF(Ergebnisse_Roh!C$2:C$21,$B40,Punktematrix!$B$2:$B$21) -> 17 | D40: =SUMIF(Ergebnisse_Roh!D$2:D$21,$B40,Punktematrix!$B$2:$B$21) -> 20 | E40: =SUMIF(Ergebnisse_Roh!E$2:E$21,$B40,Punktematrix!$B$2:$B$21) -> 30 | F40: =SUMIF(Ergebnisse_Roh!F$2:F$21,$B40,Punktematrix!$B$2:$B$21) -> 0 | G40: =SUMIF(Ergebnisse_Roh!G$2:G$21,$B40,Punktematrix!$B$2:$B$21) -> 0 | H40: =SUMIF(Ergebnisse_Roh!H$2:H$21,$B40,Punktematrix!$B$2:$B$21) -> 30 | I40: =SUMIF(Ergebnisse_Roh!I$2:I$21,$B40,Punktematrix!$B$2:$B$21) -> 5 | J40: =SUMIF(Ergebnisse_Roh!J$2:J$21,$B40,Punktematrix!$B$2:$B$21) -> 5 | K40: =SUMIF(Ergebnisse_Roh!K$2:K$21,$B40,Punktematrix!$B$2:$B$21) -> 10
...

Sheet Ergebnisse_Roh
A1: Etappe | B1: Platz | C1: S01 | D1: S02 | E1: S03 | F1: S04 | G1: S05 | H1: S06 | I1: S07 | J1: S08 | K1: S09
A2: 1 | B2: 1 | C2: VingegaardJonasTeam Visma | Lease a Bike | D2: del ToroIsaacUAE Team Emirates - XRG | E2: PogačarTadejUAE Team Emirates - XRG | F2: PedersenMadsLidl - Trek | G2: KooijOlavDecathlon CMA CGM Team | H2: PogačarTadejUAE Team Emirates - XRG | I2: MerlierTimSoudal Quick-Step | J2: MerlierTimSoudal Quick-Step | K2: van der PoelMathieuAlpecin - Premier Tech
A3: 1 | B3: 2 | C3: GannaFilippoNetcompany INEOS | D3: PogačarTadejUAE Team Emirates - XRG | E3: VingegaardJonasTeam Visma | Lease a Bike | F3: SimmonsQuinnLidl - Trek | G3: KanterMaxXDS Astana Team | H3: VingegaardJonasTeam Visma | Lease a Bike | I3: WærenskjoldSørenUno-X Mobility | J3: GirmayBiniamNSN Cycling Team | K3: JohannessenTobias HallandUno-X Mobility
A4: 1 | B4: 3 | C4: PogačarTadejUAE Team Emirates - XRG | D4: EvenepoelRemcoRed Bull - BORA - hansgrohe | E4: CarapazRichardEF Education - EasyPost | F4: García PiernaRaúlMovistar Team | G4: MerlierTimSoudal Quick-Step | H4: del ToroIsaacUAE Team Emirates - XRG | I4: GirmayBiniamNSN Cycling Team | J4: KooijOlavDecathlon CMA CGM Team | K4: PidcockTomPinarello Q36.5 Pro Cycling Team
A5: 1 | B5: 4 | C5: AyusoJuanLidl - Trek | D5: VingegaardJonasTeam Visma | Lease a Bike | E5: SeixasPaulDecathlon CMA CGM Team | F5: FrigoMarcoNSN Cycling Team | G5: ArtzHuubLotto Intermarché | H5: EvenepoelRemcoRed Bull - BORA - hansgrohe | I5: KanterMaxXDS Astana Team | J5: PhilipsenJasperAlpecin - Premier Tech | K5: BaudinAlexEF Education - EasyPost
A6: 1 | B6: 5 | C6: EvenepoelRemcoRed Bull - BORA - hansgrohe | D6: SkjelmoseMattiasLidl - Trek | E6: JohannessenTobias HallandUno-X Mobility | F6: DebruyneRamsesAlpecin - Premier Tech | G6: PhilipsenJasperAlpecin - Premier Tech | H6: SeixasPaulDecathlon CMA CGM Team | I6: PhilipsenJasperAlpecin - Premier Tech | J6: BittnerPavelTeam Picnic PostNL | K6: GannaFilippoNetcompany INEOS
A7: 1 | B7: 6 | C7: del ToroIsaacUAE Team Emirates - XRG | D7: JohannessenTobias HallandUno-X Mobility | E7: Van EetveltLennertLotto Intermarché | F7: VauquelinKévinNetcompany INEOS | G7: GirmayBiniamNSN Cycling Team | H7: LipowitzFlorianRed Bull - BORA - hansgrohe | I7: BauhausPhilBahrain - Victorious | J7: AckermannPascalTeam Jayco AlUla | K7: MatthewsMichaelTeam Jayco AlUla
A8: 1 | B8: 7 | C8: PiganzoliDavideTeam Visma | Lease a Bike | D8: GrégoireRomainGroupama - FDJ United | E8: LipowitzFlorianRed Bull - BORA - hansgrohe | F8: QuinnSeanEF Education - EasyPost | G8: PedersenMadsLidl - Trek | H8: AyusoJuanLidl - Trek | I8: ArtzHuubLotto Intermarché | J8: PluimersRickTudor Pro Cycling Team | K8: PedersenMadsLidl - Trek
A9: 1 | B9: 8 | C9: LipowitzFlorianRed Bull - BORA - hansgrohe | D9: SeixasPaulDecathlon CMA CGM Team | E9: del ToroIsaacUAE Team Emirates - XRG | F9: TræenTorsteinUno-X Mobility | G9: FretinMilanCofidis | H9: SkjelmoseMattiasLidl - Trek | I9: GodonDorianNetcompany INEOS | J9: RussoClémentGroupama - FDJ United | K9: BreuillardNicolasTotalEnergies
A10: 1 | B10: 9 | C10: SeixasPaulDecathlon CMA CGM Team | D10: MartinezLennyBahrain - Victorious | E10: EvenepoelRemcoRed Bull - BORA - hansgrohe | F10: VacekMathiasLidl - Trek | G10: WærenskjoldSørenUno-X Mobility | H10: KussSeppTeam Visma | Lease a Bike | I10: PedersenMadsLidl - Trek | J10: KanterMaxXDS Astana Team | K10: JegatJordanTotalEnergies
A11: 1 | B11: 10 | C11: FossTobiasNetcompany INEOS | D11: PidcockTomPinarello Q36.5 Pro Cycling Team | E11: AyusoJuanLidl - Trek | F11: CastrilloPabloMovistar Team | G11: TurgisAnthonyTotalEnergies | H11: MartinezLennyBahrain - Victorious | I11: Van AsbroeckTomNSN Cycling Team | J11: FretinMilanCofidis | K11: QuinnSeanEF Education - EasyPost
A12: 1 | B12: 11 | C12: van der PoelMathieuAlpecin - Premier Tech | D12: Van EetveltLennertLotto Intermarché | E12: SkjelmoseMattiasLidl - Trek | F12: MatthewsMichaelTeam Jayco AlUla | G12: BerckmoesJennoLotto Intermarché | H12: BernalEganNetcompany INEOS | I12: BittnerPavelTeam Picnic PostNL | J12: WærenskjoldSørenUno-X Mobility | K12: PogačarTadejUAE Team Emirates - XRG
A13: 1 | B13: 12 | C13: GrégoireRomainGroupama - FDJ United | D13: AyusoJuanLidl - Trek | E13: Van WilderIlanSoudal Quick-Step | F13: DelettreAlexandreTotalEnergies | G13: AckermannPascalTeam Jayco AlUla | H13: JegatJordanTotalEnergies | I13: AckermannPascalTeam Jayco AlUla | J13: PedersenMadsLidl - Trek | K13: EvenepoelRemcoRed Bull - BORA - hansgrohe
... A16: 1 | B16: 15 | C16: MartinezLennyBahrain - Victorious | D16: BaudinAlexEF Education - EasyPost | E16: PidcockTomPinarello Q36.5 Pro Cycling Team | F16: MolenaarAlexCaja Rural - Seguros RGA | G16: GodonDorianNetcompany INEOS | H16: PidcockTomPinarello Q36.5 Pro Cycling Team | I16: TurgisAnthonyTotalEnergies | J16: van der PoelMathieuAlpecin - Premier Tech | K16: BenootTiesjDecathlon CMA CGM Team
A17: 1 | B17: Gelb | C17: VingegaardJonasTeam Visma | Lease a Bike | D17: VingegaardJonasTeam Visma | Lease a Bike | E17: PogačarTadejUAE Team Emirates - XRG | F17: TræenTorsteinUno-X Mobility | G17: TræenTorsteinUno-X Mobility | H17: PogačarTadejUAE Team Emirates - XRG | I17: PogačarTadejUAE Team Emirates - XRG | J17: PogačarTadejUAE Team Emirates - XRG | K17: PogačarTadejUAE Team Emirates - XRG
A18: 1 | B18: Grün | C18: BernalEganNetcompany INEOS | D18: del ToroIsaacUAE Team Emirates - XRG | E18: PogačarTadejUAE Team Emirates - XRG | F18: PedersenMadsLidl - Trek | G18: PedersenMadsLidl - Trek | H18: PedersenMadsLidl - Trek | I18: PedersenMadsLidl - Trek | J18: PedersenMadsLidl - Trek | K18: PedersenMadsLidl - Trek
A19: 1 | B19: Weiß | C19: AyusoJuanLidl - Trek | D19: del ToroIsaacUAE Team Emirates - XRG | E19: del ToroIsaacUAE Team Emirates - XRG | F19: VacekMathiasLidl - Trek | G19: VacekMathiasLidl - Trek | H19: del ToroIsaacUAE Team Emirates - XRG | I19: del ToroIsaacUAE Team Emirates - XRG | J19: del ToroIsaacUAE Team Emirates - XRG | K19: del ToroIsaacUAE Team Emirates - XRG
A20: 1 | B20: Berg | C20: PogačarTadejUAE Team Emirates - XRG | D20: MolenaarAlexCaja Rural - Seguros RGA | E20: BaudinAlexEF Education - EasyPost | F20: BaudinAlexEF Education - EasyPost | G20: BaudinAlexEF Education - EasyPost | H20: PogačarTadejUAE Team Emirates - XRG | I20: PogačarTadejUAE Team Emirates - XRG | J20: PogačarTadejUAE Team Emirates - XRG | K20: PogačarTadejUAE Team Emirates - XRG
A21: 1 | B21: Mannschaft | C21: Netcompany INEOS | D21: UAE Team Emirates - XRG | E21: UAE Team Emirates - XRG | F21: Lidl - Trek | G21: XDS Astana Team | H21: UAE Team Emirates - XRG | I21: XDS Astana Team | J21: Team Picnic PostNL | K21: EF Education - EasyPost

Sheet Startlist2026
A1: BIB | B1: Specialty | C1: Age | D1: Rider | E1: Team | F1: S01 | G1: S02 | H1: S03 | I1: S04 | J1: S05 | K1: S06 | L1: S07 | M1: S08 | N1: S09
A2: 1 | B2: Climber | C2: 27 | D2: PogačarTadejUAE Team Emirates - XRG | E2: UAE Team Emirates - XRG | F2: =SUMIF(Ergebnisse_Roh!C$2:C$21,$D2,Punktematrix!$B$2:$B$21) -> 17 | G2: =SUMIF(Ergebnisse_Roh!D$2:D$21,$D2,Punktematrix!$B$2:$B$21) -> 20 | H2: =SUMIF(Ergebnisse_Roh!E$2:E$21,$D2,Punktematrix!$B$2:$B$21) -> 30 | I2: =SUMIF(Ergebnisse_Roh!F$2:F$21,$D2,Punktematrix!$B$2:$B$21) -> 0 | J2: =SUMIF(Ergebnisse_Roh!G$2:G$21,$D2,Punktematrix!$B$2:$B$21) -> 0 | K2: =SUMIF(Ergebnisse_Roh!H$2:H$21,$D2,Punktematrix!$B$2:$B$21) -> 30 | L2: =SUMIF(Ergebnisse_Roh!I$2:I$21,$D2,Punktematrix!$B$2:$B$21) -> 5 | M2: =SUMIF(Ergebnisse_Roh!J$2:J$21,$D2,Punktematrix!$B$2:$B$21) -> 5 | N2: =SUMIF(Ergebnisse_Roh!K$2:K$21,$D2,Punktematrix!$B$2:$B$21) -> 10
A3: 2 | B3: GC | C3: 22 | D3: del ToroIsaacUAE Team Emirates - XRG | E3: UAE Team Emirates - XRG | F3: =SUMIF(Ergebnisse_Roh!C$2:C$21,$D3,Punktematrix!$B$2:$B$21) -> 10 | G3: =SUMIF(Ergebnisse_Roh!D$2:D$21,$D3,Punktematrix!$B$2:$B$21) -> 29 | H3: =SUMIF(Ergebnisse_Roh!E$2:E$21,$D3,Punktematrix!$B$2:$B$21) -> 10 | I3: =SUMIF(Ergebnisse_Roh!F$2:F$21,$D3,Punktematrix!$B$2:$B$21) -> 0 | J3: =SUMIF(Ergebnisse_Roh!G$2:G$21,$D3,Punktematrix!$B$2:$B$21) -> 0 | K3: =SUMIF(Ergebnisse_Roh!H$2:H$21,$D3,Punktematrix!$B$2:$B$21) -> 17 | L3: =SUMIF(Ergebnisse_Roh!I$2:I$21,$D3,Punktematrix!$B$2:$B$21) -> 2 | M3: =SUMIF(Ergebnisse_Roh!J$2:J$21,$D3,Punktematrix!$B$2:$B$21) -> 2 | N3: =SUMIF(Ergebnisse_Roh!K$2:K$21,$D3,Punktematrix!$B$2:$B$21) -> 5
A4: 3 | B4: GC | C4: 32 | D4: GroßschartnerFelixUAE Team Emirates - XRG | E4: UAE Team Emirates - XRG | F4: =SUMIF(Ergebnisse_Roh!C$2:C$21,$D4,Punktematrix!$B$2:$B$21) -> 0 | G4: =SUMIF(Ergebnisse_Roh!D$2:D$21,$D4,Punktematrix!$B$2:$B$21) -> 0 | H4: =SUMIF(Ergebnisse_Roh!E$2:E$21,$D4,Punktematrix!$B$2:$B$21) -> 0 | I4: =SUMIF(Ergebnisse_Roh!F$2:F$21,$D4,Punktematrix!$B$2:$B$21) -> 0 | J4: =SUMIF(Ergebnisse_Roh!G$2:G$21,$D4,Punktematrix!$B$2:$B$21) -> 0 | K4: =SUMIF(Ergebnisse_Roh!H$2:H$21,$D4,Punktematrix!$B$2:$B$21) -> 0 | L4: =SUMIF(Ergebnisse_Roh!I$2:I$21,$D4,Punktematrix!$B$2:$B$21) -> 0 | M4: =SUMIF(Ergebnisse_Roh!J$2:J$21,$D4,Punktematrix!$B$2:$B$21) -> 0 | N4: =SUMIF(Ergebnisse_Roh!K$2:K$21,$D4,Punktematrix!$B$2:$B$21) -> 0
A5: 4 | B5: GC | C5: 28 | D5: McNultyBrandonUAE Team Emirates - XRG | E5: UAE Team Emirates - XRG | F5: =SUMIF(Ergebnisse_Roh!C$2:C$21,$D5,Punktematrix!$B$2:$B$21) -> 0 | G5: =SUMIF(Ergebnisse_Roh!D$2:D$21,$D5,Punktematrix!$B$2:$B$21) -> 0 | H5: =SUMIF(Ergebnisse_Roh!E$2:E$21,$D5,Punktematrix!$B$2:$B$21) -> 0 | I5: =SUMIF(Ergebnisse_Roh!F$2:F$21,$D5,Punktematrix!$B$2:$B$21) -> 0 | J5: =SUMIF(Ergebnisse_Roh!G$2:G$21,$D5,Punktematrix!$B$2:$B$21) -> 0 | K5: =SUMIF(Ergebnisse_Roh!H$2:H$21,$D5,Punktematrix!$B$2:$B$21) -> 0 | L5: =SUMIF(Ergebnisse_Roh!I$2:I$21,$D5,Punktematrix!$B$2:$B$21) -> 0 | M5: =SUMIF(Ergebnisse_Roh!J$2:J$21,$D5,Punktematrix!$B$2:$B$21) -> 0 | N5: =SUMIF(Ergebnisse_Roh!K$2:K$21,$D5,Punktematrix!$B$2:$B$21) -> 0
A6: 5 | B6: Classic | C6: 32 | D6: PolittNilsUAE Team Emirates - XRG | E6: UAE Team Emirates - XRG | F6: =SUMIF(Ergebnisse_Roh!C$2:C$21,$D6,Punktematrix!$B$2:$B$21) -> 0 | G6: =SUMIF(Ergebnisse_Roh!D$2:D$21,$D6,Punktematrix!$B$2:$B$21) -> 0 | H6: =SUMIF(Ergebnisse_Roh!E$2:E$21,$D6,Punktematrix!$B$2:$B$21) -> 0 | I6: =SUMIF(Ergebnisse_Roh!F$2:F$21,$D6,Punktematrix!$B$2:$B$21) -> 0 | J6: =SUMIF(Ergebnisse_Roh!G$2:G$21,$D6,Punktematrix!$B$2:$B$21) -> 0 | K6: =SUMIF(Ergebnisse_Roh!H$2:H$21,$D6,Punktematrix!$B$2:$B$21) -> 0 | L6: =SUMIF(Ergebnisse_Roh!I$2:I$21,$D6,Punktematrix!$B$2:$B$21) -> 0 | M6: =SUMIF(Ergebnisse_Roh!J$2:J$21,$D6,Punktematrix!$B$2:$B$21) -> 0 | N6: =SUMIF(Ergebnisse_Roh!K$2:K$21,$D6,Punktematrix!$B$2:$B$21) -> 0
A7: 6 | B7: Classic | C7: 27 | D7: VermeerschFlorianUAE Team Emirates - XRG | E7: UAE Team Emirates - XRG | F7: =SUMIF(Ergebnisse_Roh!C$2:C$21,$D7,Punktematrix!$B$2:$B$21) -> 0 | G7: =SUMIF(Ergebnisse_Roh!D$2:D$21,$D7,Punktematrix!$B$2:$B$21) -> 0 | H7: =SUMIF(Ergebnisse_Roh!E$2:E$21,$D7,Punktematrix!$B$2:$B$21) -> 0 | I7: =SUMIF(Ergebnisse_Roh!F$2:F$21,$D7,Punktematrix!$B$2:$B$21) -> 0 | J7: =SUMIF(Ergebnisse_Roh!G$2:G$21,$D7,Punktematrix!$B$2:$B$21) -> 0 | K7: =SUMIF(Ergebnisse_Roh!H$2:H$21,$D7,Punktematrix!$B$2:$B$21) -> 0 | L7: =SUMIF(Ergebnisse_Roh!I$2:I$21,$D7,Punktematrix!$B$2:$B$21) -> 0 | M7: =SUMIF(Ergebnisse_Roh!J$2:J$21,$D7,Punktematrix!$B$2:$B$21) -> 0 | N7: =SUMIF(Ergebnisse_Roh!K$2:K$21,$D7,Punktematrix!$B$2:$B$21) -> 0
A8: 7 | B8: GC | C8: 35 | D8: WellensTimUAE Team Emirates - XRG | E8: UAE Team Emirates - XRG | F8: =SUMIF(Ergebnisse_Roh!C$2:C$21,$D8,Punktematrix!$B$2:$B$21) -> 0 | G8: =SUMIF(Ergebnisse_Roh!D$2:D$21,$D8,Punktematrix!$B$2:$B$21) -> 0 | H8: =SUMIF(Ergebnisse_Roh!E$2:E$21,$D8,Punktematrix!$B$2:$B$21) -> 0 | I8: =SUMIF(Ergebnisse_Roh!F$2:F$21,$D8,Punktematrix!$B$2:$B$21) -> 0 | J8: =SUMIF(Ergebnisse_Roh!G$2:G$21,$D8,Punktematrix!$B$2:$B$21) -> 0 | K8: =SUMIF(Ergebnisse_Roh!H$2:H$21,$D8,Punktematrix!$B$2:$B$21) -> 0 | L8: =SUMIF(Ergebnisse_Roh!I$2:I$21,$D8,Punktematrix!$B$2:$B$21) -> 0 | M8: =SUMIF(Ergebnisse_Roh!J$2:J$21,$D8,Punktematrix!$B$2:$B$21) -> 0 | N8: =SUMIF(Ergebnisse_Roh!K$2:K$21,$D8,Punktematrix!$B$2:$B$21) -> 0
A9: 8 | B9: Climber | C9: 33 | D9: YatesAdamUAE Team Emirates - XRG | E9: UAE Team Emirates - XRG | F9: =SUMIF(Ergebnisse_Roh!C$2:C$21,$D9,Punktematrix!$B$2:$B$21) -> 0 | G9: =SUMIF(Ergebnisse_Roh!D$2:D$21,$D9,Punktematrix!$B$2:$B$21) -> 0 | H9: =SUMIF(Ergebnisse_Roh!E$2:E$21,$D9,Punktematrix!$B$2:$B$21) -> 0 | I9: =SUMIF(Ergebnisse_Roh!F$2:F$21,$D9,Punktematrix!$B$2:$B$21) -> 0 | J9: =SUMIF(Ergebnisse_Roh!G$2:G$21,$D9,Punktematrix!$B$2:$B$21) -> 0 | K9: =SUMIF(Ergebnisse_Roh!H$2:H$21,$D9,Punktematrix!$B$2:$B$21) -> 0 | L9: =SUMIF(Ergebnisse_Roh!I$2:I$21,$D9,Punktematrix!$B$2:$B$21) -> 0 | M9: =SUMIF(Ergebnisse_Roh!J$2:J$21,$D9,Punktematrix!$B$2:$B$21) -> 0 | N9: =SUMIF(Ergebnisse_Roh!K$2:K$21,$D9,Punktematrix!$B$2:$B$21) -> 0
A10: 11 | B10: GC | C10: 29 | D10: VingegaardJonasTeam Visma | Lease a Bike | E10: Team Visma | Lease a Bike | F10: =SUMIF(Ergebnisse_Roh!C$2:C$21,$D10,Punktematrix!$B$2:$B$21) -> 28 | G10: =SUMIF(Ergebnisse_Roh!D$2:D$21,$D10,Punktematrix!$B$2:$B$21) -> 15 | H10: =SUMIF(Ergebnisse_Roh!E$2:E$21,$D10,Punktematrix!$B$2:$B$21) -> 20 | I10: =SUMIF(Ergebnisse_Roh!F$2:F$21,$D10,Punktematrix!$B$2:$B$21) -> 0 | J10: =SUMIF(Ergebnisse_Roh!G$2:G$21,$D10,Punktematrix!$B$2:$B$21) -> 0 | K10: =SUMIF(Ergebnisse_Roh!H$2:H$21,$D10,Punktematrix!$B$2:$B$21) -> 20 | L10: =SUMIF(Ergebnisse_Roh!I$2:I$21,$D10,Punktematrix!$B$2:$B$21) -> 0 | M10: =SUMIF(Ergebnisse_Roh!J$2:J$21,$D10,Punktematrix!$B$2:$B$21) -> 0 | N10: =SUMIF(Ergebnisse_Roh!K$2:K$21,$D10,Punktematrix!$B$2:$B$21) -> 0
A11: 12 | B11: TT | C11: 30 | D11: AffiniEdoardoTeam Visma | Lease a Bike | E11: Team Visma | Lease a Bike | F11: =SUMIF(Ergebnisse_Roh!C$2:C$21,$D11,Punktematrix!$B$2:$B$21) -> 0 | G11: =SUMIF(Ergebnisse_Roh!D$2:D$21,$D11,Punktematrix!$B$2:$B$21) -> 0 | H11: =SUMIF(Ergebnisse_Roh!E$2:E$21,$D11,Punktematrix!$B$2:$B$21) -> 0 | I11: =SUMIF(Ergebnisse_Roh!F$2:F$21,$D11,Punktematrix!$B$2:$B$21) -> 0 | J11: =SUMIF(Ergebnisse_Roh!G$2:G$21,$D11,Punktematrix!$B$2:$B$21) -> 0 | K11: =SUMIF(Ergebnisse_Roh!H$2:H$21,$D11,Punktematrix!$B$2:$B$21) -> 0 | L11: =SUMIF(Ergebnisse_Roh!I$2:I$21,$D11,Punktematrix!$B$2:$B$21) -> 0 | M11: =SUMIF(Ergebnisse_Roh!J$2:J$21,$D11,Punktematrix!$B$2:$B$21) -> 0 | N11: =SUMIF(Ergebnisse_Roh!K$2:K$21,$D11,Punktematrix!$B$2:$B$21) -> 0
A12: 13 | B12: TT | C12: 32 | D12: ArmirailBrunoTeam Visma | Lease a Bike | E12: Team Visma | Lease a Bike | F12: =SUMIF(Ergebnisse_Roh!C$2:C$21,$D12,Punktematrix!$B$2:$B$21) -> 0 | G12: =SUMIF(Ergebnisse_Roh!D$2:D$21,$D12,Punktematrix!$B$2:$B$21) -> 0 | H12: =SUMIF(Ergebnisse_Roh!E$2:E$21,$D12,Punktematrix!$B$2:$B$21) -> 0 | I12: =SUMIF(Ergebnisse_Roh!F$2:F$21,$D12,Punktematrix!$B$2:$B$21) -> 0 | J12: =SUMIF(Ergebnisse_Roh!G$2:G$21,$D12,Punktematrix!$B$2:$B$21) -> 0 | K12: =SUMIF(Ergebnisse_Roh!H$2:H$21,$D12,Punktematrix!$B$2:$B$21) -> 0 | L12: =SUMIF(Ergebnisse_Roh!I$2:I$21,$D12,Punktematrix!$B$2:$B$21) -> 0 | M12: =SUMIF(Ergebnisse_Roh!J$2:J$21,$D12,Punktematrix!$B$2:$B$21) -> 0 | N12: =SUMIF(Ergebnisse_Roh!K$2:K$21,$D12,Punktematrix!$B$2:$B$21) -> 0
A13: 14 | B13: TT | C13: 34 | D13: CampenaertsVictorTeam Visma | Lease a Bike | E13: Team Visma | Lease a Bike | F13: =SUMIF(Ergebnisse_Roh!C$2:C$21,$D13,Punktematrix!$B$2:$B$21) -> 0 | G13: =SUMIF(Ergebnisse_Roh!D$2:D$21,$D13,Punktematrix!$B$2:$B$21) -> 0 | H13: =SUMIF(Ergebnisse_Roh!E$2:E$21,$D13,Punktematrix!$B$2:$B$21) -> 0 | I13: =SUMIF(Ergebnisse_Roh!F$2:F$21,$D13,Punktematrix!$B$2:$B$21) -> 0 | J13: =SUMIF(Ergebnisse_Roh!G$2:G$21,$D13,Punktematrix!$B$2:$B$21) -> 0 | K13: =SUMIF(Ergebnisse_Roh!H$2:H$21,$D13,Punktematrix!$B$2:$B$21) -> 0 | L13: =SUMIF(Ergebnisse_Roh!I$2:I$21,$D13,Punktematrix!$B$2:$B$21) -> 0 | M13: =SUMIF(Ergebnisse_Roh!J$2:J$21,$D13,Punktematrix!$B$2:$B$21) -> 0 | N13: =SUMIF(Ergebnisse_Roh!K$2:K$21,$D13,Punktematrix!$B$2:$B$21) -> 0
... A185: 228 | B185: GC | C185: 29 | D185: ParraJosé FélixCaja Rural - Seguros RGA | E185: Caja Rural - Seguros RGA | F185: =SUMIF(Ergebnisse_Roh!C$2:C$21,$D185,Punktematrix!$B$2:$B$21) -> 0 | G185: =SUMIF(Ergebnisse_Roh!D$2:D$21,$D185,Punktematrix!$B$2:$B$21) -> 0 | H185: =SUMIF(Ergebnisse_Roh!E$2:E$21,$D185,Punktematrix!$B$2:$B$21) -> 0 | I185: =SUMIF(Ergebnisse_Roh!F$2:F$21,$D185,Punktematrix!$B$2:$B$21) -> 0 | J185: =SUMIF(Ergebnisse_Roh!G$2:G$21,$D185,Punktematrix!$B$2:$B$21) -> 0 | K185: =SUMIF(Ergebnisse_Roh!H$2:H$21,$D185,Punktematrix!$B$2:$B$21) -> 0 | L185: =SUMIF(Ergebnisse_Roh!I$2:I$21,$D185,Punktematrix!$B$2:$B$21) -> 0 | M185: =SUMIF(Ergebnisse_Roh!J$2:J$21,$D185,Punktematrix!$B$2:$B$21) -> 0 | N185: =SUMIF(Ergebnisse_Roh!K$2:K$21,$D185,Punktematrix!$B$2:$B$21) -> 0
D186: Caja Rural - Seguros RGA | F186: =SUMIF(Ergebnisse_Roh!C$2:C$21,$D186,Punktematrix!$B$2:$B$21) -> 0 | G186: =SUMIF(Ergebnisse_Roh!D$2:D$21,$D186,Punktematrix!$B$2:$B$21) -> 0 | H186: =SUMIF(Ergebnisse_Roh!E$2:E$21,$D186,Punktematrix!$B$2:$B$21) -> 0 | I186: =SUMIF(Ergebnisse_Roh!F$2:F$21,$D186,Punktematrix!$B$2:$B$21) -> 0 | J186: =SUMIF(Ergebnisse_Roh!G$2:G$21,$D186,Punktematrix!$B$2:$B$21) -> 0 | K186: =SUMIF(Ergebnisse_Roh!H$2:H$21,$D186,Punktematrix!$B$2:$B$21) -> 0 | L186: =SUMIF(Ergebnisse_Roh!I$2:I$21,$D186,Punktematrix!$B$2:$B$21) -> 0 | M186: =SUMIF(Ergebnisse_Roh!J$2:J$21,$D186,Punktematrix!$B$2:$B$21) -> 0 | N186: =SUMIF(Ergebnisse_Roh!K$2:K$21,$D186,Punktematrix!$B$2:$B$21) -> 0
D187: Team Picnic PostNL | F187: =SUMIF(Ergebnisse_Roh!C$2:C$21,$D187,Punktematrix!$B$2:$B$21) -> 0 | G187: =SUMIF(Ergebnisse_Roh!D$2:D$21,$D187,Punktematrix!$B$2:$B$21) -> 0 | H187: =SUMIF(Ergebnisse_Roh!E$2:E$21,$D187,Punktematrix!$B$2:$B$21) -> 0 | I187: =SUMIF(Ergebnisse_Roh!F$2:F$21,$D187,Punktematrix!$B$2:$B$21) -> 0 | J187: =SUMIF(Ergebnisse_Roh!G$2:G$21,$D187,Punktematrix!$B$2:$B$21) -> 0 | K187: =SUMIF(Ergebnisse_Roh!H$2:H$21,$D187,Punktematrix!$B$2:$B$21) -> 0 | L187: =SUMIF(Ergebnisse_Roh!I$2:I$21,$D187,Punktematrix!$B$2:$B$21) -> 0 | M187: =SUMIF(Ergebnisse_Roh!J$2:J$21,$D187,Punktematrix!$B$2:$B$21) -> 2 | N187: =SUMIF(Ergebnisse_Roh!K$2:K$21,$D187,Punktematrix!$B$2:$B$21) -> 0
D188: TotalEnergies | F188: =SUMIF(Ergebnisse_Roh!C$2:C$21,$D188,Punktematrix!$B$2:$B$21) -> 0 | G188: =SUMIF(Ergebnisse_Roh!D$2:D$21,$D188,Punktematrix!$B$2:$B$21) -> 0 | H188: =SUMIF(Ergebnisse_Roh!E$2:E$21,$D188,Punktematrix!$B$2:$B$21) -> 0 | I188: =SUMIF(Ergebnisse_Roh!F$2:F$21,$D188,Punktematrix!$B$2:$B$21) -> 0 | J188: =SUMIF(Ergebnisse_Roh!G$2:G$21,$D188,Punktematrix!$B$2:$B$21) -> 0 | K188: =SUMIF(Ergebnisse_Roh!H$2:H$21,$D188,Punktematrix!$B$2:$B$21) -> 0 | L188: =SUMIF(Ergebnisse_Roh!I$2:I$21,$D188,Punktematrix!$B$2:$B$21) -> 0 | M188: =SUMIF(Ergebnisse_Roh!J$2:J$21,$D188,Punktematrix!$B$2:$B$21) -> 0 | N188: =SUMIF(Ergebnisse_Roh!K$2:K$21,$D188,Punktematrix!$B$2:$B$21) -> 0
D189: Groupama - FDJ United | F189: =SUMIF(Ergebnisse_Roh!C$2:C$21,$D189,Punktematrix!$B$2:$B$21) -> 0 | G189: =SUMIF(Ergebnisse_Roh!D$2:D$21,$D189,Punktematrix!$B$2:$B$21) -> 0 | H189: =SUMIF(Ergebnisse_Roh!E$2:E$21,$D189,Punktematrix!$B$2:$B$21) -> 0 | I189: =SUMIF(Ergebnisse_Roh!F$2:F$21,$D189,Punktematrix!$B$2:$B$21) -> 0 | J189: =SUMIF(Ergebnisse_Roh!G$2:G$21,$D189,Punktematrix!$B$2:$B$21) -> 0 | K189: =SUMIF(Ergebnisse_Roh!H$2:H$21,$D189,Punktematrix!$B$2:$B$21) -> 0 | L189: =SUMIF(Ergebnisse_Roh!I$2:I$21,$D189,Punktematrix!$B$2:$B$21) -> 0 | M189: =SUMIF(Ergebnisse_Roh!J$2:J$21,$D189,Punktematrix!$B$2:$B$21) -> 0 | N189: =SUMIF(Ergebnisse_Roh!K$2:K$21,$D189,Punktematrix!$B$2:$B$21) -> 0
D190: Tudor Pro Cycling Team | F190: =SUMIF(Ergebnisse_Roh!C$2:C$21,$D190,Punktematrix!$B$2:$B$21) -> 0 | G190: =SUMIF(Ergebnisse_Roh!D$2:D$21,$D190,Punktematrix!$B$2:$B$21) -> 0 | H190: =SUMIF(Ergebnisse_Roh!E$2:E$21,$D190,Punktematrix!$B$2:$B$21) -> 0 | I190: =SUMIF(Ergebnisse_Roh!F$2:F$21,$D190,Punktematrix!$B$2:$B$21) -> 0 | J190: =SUMIF(Ergebnisse_Roh!G$2:G$21,$D190,Punktematrix!$B$2:$B$21) -> 0 | K190: =SUMIF(Ergebnisse_Roh!H$2:H$21,$D190,Punktematrix!$B$2:$B$21) -> 0 | L190: =SUMIF(Ergebnisse_Roh!I$2:I$21,$D190,Punktematrix!$B$2:$B$21) -> 0 | M190: =SUMIF(Ergebnisse_Roh!J$2:J$21,$D190,Punktematrix!$B$2:$B$21) -> 0 | N190: =SUMIF(Ergebnisse_Roh!K$2:K$21,$D190,Punktematrix!$B$2:$B$21) -> 0
D191: Pinarello Q36.5 Pro Cycling Team | F191: =SUMIF(Ergebnisse_Roh!C$2:C$21,$D191,Punktematrix!$B$2:$B$21) -> 0 | G191: =SUMIF(Ergebnisse_Roh!D$2:D$21,$D191,Punktematrix!$B$2:$B$21) -> 0 | H191: =SUMIF(Ergebnisse_Roh!E$2:E$21,$D191,Punktematrix!$B$2:$B$21) -> 0 | I191: =SUMIF(Ergebnisse_Roh!F$2:F$21,$D191,Punktematrix!$B$2:$B$21) -> 0 | J191: =SUMIF(Ergebnisse_Roh!G$2:G$21,$D191,Punktematrix!$B$2:$B$21) -> 0 | K191: =SUMIF(Ergebnisse_Roh!H$2:H$21,$D191,Punktematrix!$B$2:$B$21) -> 0 | L191: =SUMIF(Ergebnisse_Roh!I$2:I$21,$D191,Punktematrix!$B$2:$B$21) -> 0 | M191: =SUMIF(Ergebnisse_Roh!J$2:J$21,$D191,Punktematrix!$B$2:$B$21) -> 0 | N191: =SUMIF(Ergebnisse_Roh!K$2:K$21,$D191,Punktematrix!$B$2:$B$21) -> 0
D192: Groupama - FDJ United | F192: =SUMIF(Ergebnisse_Roh!C$2:C$21,$D192,Punktematrix!$B$2:$B$21) -> 0 | G192: =SUMIF(Ergebnisse_Roh!D$2:D$21,$D192,Punktematrix!$B$2:$B$21) -> 0 | H192: =SUMIF(Ergebnisse_Roh!E$2:E$21,$D192,Punktematrix!$B$2:$B$21) -> 0 | I192: =SUMIF(Ergebnisse_Roh!F$2:F$21,$D192,Punktematrix!$B$2:$B$21) -> 0 | J192: =SUMIF(Ergebnisse_Roh!G$2:G$21,$D192,Punktematrix!$B$2:$B$21) -> 0 | K192: =SUMIF(Ergebnisse_Roh!H$2:H$21,$D192,Punktematrix!$B$2:$B$21) -> 0 | L192: =SUMIF(Ergebnisse_Roh!I$2:I$21,$D192,Punktematrix!$B$2:$B$21) -> 0 | M192: =SUMIF(Ergebnisse_Roh!J$2:J$21,$D192,Punktematrix!$B$2:$B$21) -> 0 | N192: =SUMIF(Ergebnisse_Roh!K$2:K$21,$D192,Punktematrix!$B$2:$B$21) -> 0
D193: Lotto Intermarché | F193: =SUMIF(Ergebnisse_Roh!C$2:C$21,$D193,Punktematrix!$B$2:$B$21) -> 0 | G193: =SUMIF(Ergebnisse_Roh!D$2:D$21,$D193,Punktematrix!$B$2:$B$21) -> 0 | H193: =SUMIF(Ergebnisse_Roh!E$2:E$21,$D193,Punktematrix!$B$2:$B$21) -> 0 | I193: =SUMIF(Ergebnisse_Roh!F$2:F$21,$D193,Punktematrix!$B$2:$B$21) -> 0 | J193: =SUMIF(Ergebnisse_Roh!G$2:G$21,$D193,Punktematrix!$B$2:$B$21) -> 0 | K193: =SUMIF(Ergebnisse_Roh!H$2:H$21,$D193,Punktematrix!$B$2:$B$21) -> 0 | L193: =SUMIF(Ergebnisse_Roh!I$2:I$21,$D193,Punktematrix!$B$2:$B$21) -> 0 | M193: =SUMIF(Ergebnisse_Roh!J$2:J$21,$D193,Punktematrix!$B$2:$B$21) -> 0 | N193: =SUMIF(Ergebnisse_Roh!K$2:K$21,$D193,Punktematrix!$B$2:$B$21) -> 0
